Workbook

Sheet Hướng dẫn
A1: CỘI: Phép thử 14 đêm trước khi code
A3: Mục đích | B3: Chạy logic dữ liệu của lớp Giấc ngủ trên 20 người thật qua Zalo. Sáng nhắn 4 câu, tối nhắn 4 câu, điền vào trang Nhật ký. Ngày 15 đọc trang Tổng kết để biết AN sẽ mời ai sang Xả áp lực, ai sang Hồi sinh lực.
A4: Trang Ngưỡng | B4: Mọi ngưỡng của logic nằm ở đây, ô vàng. Đổi ngưỡng thì toàn bộ Tổng kết tính lại. Không sửa công thức ở nơi khác.
A5: Trang Nhật ký | B5: Mỗi người 14 dòng, đã tạo sẵn P01 đến P20. Chỉ điền cột E đến M (ô vàng). Cột N trở đi là công thức, màu xám, không sửa. P01 và P02 là dữ liệu ví dụ, xóa trước khi nhập thật.
A6: Câu hỏi sáng | B6: vao_giac: tối qua vào giấc thế nào (1 khó, 5 dễ). tinh_dem: tỉnh giữa đêm mấy lần (0, 1, 2 là 2 trở lên). sang_day: sáng nay người ra sao (1 mệt, 5 khỏe). dau_truoc_ngu: lúc nằm xuống đầu thế nào (Yên / Nghĩ nhiều / Lo hồi hộp / Bực).
A7: Câu hỏi tối | B7: cang_ngay: hôm nay căng mức mấy (1 đến 5). nguon_cang: chỉ hỏi khi căng từ 4 (Việc / Tiền / Người / Không rõ). gio_an_toi: ăn tối xong lúc mấy giờ. gio_tat_den: dự định tắt đèn lúc. xong_viec: có làm Việc Tối không (1 hoặc 0), từ ngày 5.
A8: Điểm Sáng | B8: Điểm = 10 × (vao_giac − 1) + 10 × (sang_day − 1) + 10 × (2 − min(tinh_dem, 2)). Thang 0 đến 100. Từ 80 là đêm đạt ngưỡng, dưới 60 là đêm vỡ.
A9: Trang Tổng kết | B9: Một dòng mỗi người. Cột KẾT LUẬN NGÀY 15 chạy theo thứ tự: đủ 10 ngày dữ liệu; ngủ bám rễ chưa (chưa thì gia hạn, trừ khi ngủ thuần đã tốt mà sáng vẫn mệt thì mời Hồi sinh lực); loại trừ gốc tiêu hóa (cần từ 4 đêm ăn muộn); mời Xả áp lực (cần từ 3 ngày căng và liên kết căng với đêm vỡ); mời Hồi sinh lực; còn lại vào Cổng Khỏe. Cột LỜI MỜI ghép từ số của chính người đó. Cột Cờ an toàn báo trường hợp cần người thật.
A10: Trang Lịch 14 đêm | B10: Gõ mã người vào ô B2 để xem 14 ô như màn hình 'Xem 14 đêm của tôi' trong app: ô tối là đêm vỡ, ô đỏ là ngày căng.
A11: Trang Tổng quan | B11: Đếm kết quả cả nhóm. Mũi khoan đúng khi hơn một nửa bám rễ.
A12: Màu | B12: Chữ xanh dương trên nền vàng: ô nhập. Chữ đen: công thức. Chữ xanh lá: lấy từ trang khác.

Sheet Ngưỡng
A1: Ngưỡng của logic dữ liệu CỘI (ô vàng là ô được phép sửa)
A2: Điểm Sáng | D2: Nhãn nguồn căng
A3: Đêm đạt ngưỡng khi Điểm Sáng từ | B3: 80 | D3: Việc | E3: Tiền | F3: Người | G3: Không rõ
A4: Đêm vỡ khi Điểm Sáng dưới | B4: 60
A5: Ngày căng khi cang_ngay từ | B5: 4 | D5: Nhãn đầu trước ngủ
A6: Ăn muộn khi ăn tối xong sau (giờ) | B6: 0.83333333 | D6: Yên | E6: Nghĩ nhiều | F6: Lo hồi hộp | G6: Bực
A7: Bước 0: đủ dữ liệu
A8: Số ngày đủ dữ liệu tối thiểu | B8: 10
A9: Số ngày căng tối thiểu | B9: 3
A10: Bước 1: bám rễ
A11: Điểm TB tuần 2 cao hơn tuần 1 ít nhất | B11: 8
A12: Số đêm đạt ngưỡng tuần 2 tối thiểu | B12: 4
A13: Bước 3: mời Xả áp lực
A14: Chênh lệch (vỡ khi căng trừ vỡ khi yên) tối thiểu | B14: 0.35
A15: Tỷ lệ vỡ khi căng tối thiểu | B15: 0.5
A16: Tỷ lệ đầu không yên tối thiểu | B16: 0.4
A17: Hoặc số ngày căng tuần 2 tối thiểu | B17: 3
A18: Bước 4: mời Hồi sinh lực
A19: Sáng dậy TB trong đêm tốt dưới | B19: 3
A20: Ngưỡng an toàn
A21: Căng mức 5 liên tiếp (ngày) | B21: 3
A22: Đêm 'Lo hồi hộp' trong 14 đêm từ | B22: 7
A23: Tỉnh đêm 2 lần trở lên liên tiếp (đêm) | B23: 10
A24: Thiếu dữ liệu liên tiếp (ngày) | B24: 4
A25: Bổ sung
A26: Số đêm ăn muộn tối thiểu để xét gốc tiêu hóa | B26: 4
A27: Ngủ thuần TB tuần 2 từ (xét sinh khí khi chưa bám rễ) | B27: 75
A29: Nguồn: các ngưỡng là giả định ban đầu của nhóm sản phẩm CỘI, chưa có số liệu thực nghiệm. Chỉnh sau phép thử 20 người.

Sheet Nhật ký
A1: Mã người | B1: Ngày | C1: Tuần | D1: Thứ | E1: vao_giac (1-5) | F1: tinh_dem (0-2) | G1: sang_day (1-5) | H1: dau_truoc_ngu | I1: cang_ngay (1-5) | J1: nguon_cang | K1: gio_an_toi | L1: gio_tat_den | M1: xong_viec (1/0) | N1: Điểm Sáng | O1: Đủ dữ liệu | P1: Đêm vỡ | Q1: Ngày căng | R1: Đầu không yên | S1: Ăn muộn | T1: Đêm đạt ngưỡng | U1: Căng 5 liên tiếp | V1: Tỉnh ≥2 liên tiếp | W1: Thiếu DL liên tiếp | X1: Điểm ngủ thuần
A2: P01 | B2: 1 | C2: =IF(B2<=7,1,2) -> 1 | E2: 2 | F2: 1 | G2: 2 | H2: Nghĩ nhiều | I2: 4 | J2: Việc | K2: 0.85416667 | L2: 0.010416667 | N2: =IF(OR(E2="",F2="",G2=""),"",10*(E2-1)+10*(G2-1)+10*(2-MIN(F2,2))) -> 30 | O2: =IF(AND(N2<>"",I2<>""),1,0) -> 1 | P2: =IF(N2="","",IF(N2<Ngưỡng!$B$4,1,0)) -> 1 | Q2: =IF(I2="","",IF(I2>=Ngưỡng!$B$5,1,0)) -> 1 | R2: =IF(H2="","",IF(H2<>"Yên",1,0)) -> 1 | S2: =IF(K2="","",IF(K2>Ngưỡng!$B$6,1,0)) -> 1 | T2: =IF(N2="","",IF(N2>=Ngưỡng!$B$3,1,0)) -> 0 | U2: =IF(I2=5,0+1,0) -> 0 | V2: =IF(AND(F2<>"",F2>=2),0+1,0) -> 0 | W2: =IF(O2=0,0+1,0) -> 0 | X2: =IF(OR(E2="",F2=""),"",ROUND((10*(E2-1)+10*(2-MIN(F2,2)))/60*100,0)) -> 33
A3: P01 | B3: 2 | C3: =IF(B3<=7,1,2) -> 1 | E3: 3 | F3: 1 | G3: 3 | H3: Yên | I3: 2 | K3: 0.8125 | L3: 0.98611111 | N3: =IF(OR(E3="",F3="",G3=""),"",10*(E3-1)+10*(G3-1)+10*(2-MIN(F3,2))) -> 50 | O3: =IF(AND(N3<>"",I3<>""),1,0) -> 1 | P3: =IF(N3="","",IF(N3<Ngưỡng!$B$4,1,0)) -> 1 | Q3: =IF(I3="","",IF(I3>=Ngưỡng!$B$5,1,0)) -> 0 | R3: =IF(H3="","",IF(H3<>"Yên",1,0)) -> 0 | S3: =IF(K3="","",IF(K3>Ngưỡng!$B$6,1,0)) -> 0 | T3: =IF(N3="","",IF(N3>=Ngưỡng!$B$3,1,0)) -> 0 | U3: =IF(I3=5,U2+1,0) -> 0 | V3: =IF(AND(F3<>"",F3>=2),V2+1,0) -> 0 | W3: =IF(O3=0,W2+1,0) -> 0 | X3: =IF(OR(E3="",F3=""),"",ROUND((10*(E3-1)+10*(2-MIN(F3,2)))/60*100,0)) -> 50
A4: P01 | B4: 3 | C4: =IF(B4<=7,1,2) -> 1 | E4: 2 | F4: 2 | G4: 2 | H4: Bực | I4: 5 | J4: Việc | K4: 0.875 | L4: 0.020833333 | N4: =IF(OR(E4="",F4="",G4=""),"",10*(E4-1)+10*(G4-1)+10*(2-MIN(F4,2))) -> 20 | O4: =IF(AND(N4<>"",I4<>""),1,0) -> 1 | P4: =IF(N4="","",IF(N4<Ngưỡng!$B$4,1,0)) -> 1 | Q4: =IF(I4="","",IF(I4>=Ngưỡng!$B$5,1,0)) -> 1 | R4: =IF(H4="","",IF(H4<>"Yên",1,0)) -> 1 | S4: =IF(K4="","",IF(K4>Ngưỡng!$B$6,1,0)) -> 1 | T4: =IF(N4="","",IF(N4>=Ngưỡng!$B$3,1,0)) -> 0 | U4: =IF(I4=5,U3+1,0) -> 1 | V4: =IF(AND(F4<>"",F4>=2),V3+1,0) -> 1 | W4: =IF(O4=0,W3+1,0) -> 0 | X4: =IF(OR(E4="",F4=""),"",ROUND((10*(E4-1)+10*(2-MIN(F4,2)))/60*100,0)) -> 17
A5: P01 | B5: 4 | C5: =IF(B5<=7,1,2) -> 1 | E5: 3 | F5: 0 | G5: 3 | H5: Yên | I5: 3 | K5: 0.82291667 | L5: 0.97916667 | N5: =IF(OR(E5="",F5="",G5=""),"",10*(E5-1)+10*(G5-1)+10*(2-MIN(F5,2))) -> 60 | O5: =IF(AND(N5<>"",I5<>""),1,0) -> 1 | P5: =IF(N5="","",IF(N5<Ngưỡng!$B$4,1,0)) -> 0 | Q5: =IF(I5="","",IF(I5>=Ngưỡng!$B$5,1,0)) -> 0 | R5: =IF(H5="","",IF(H5<>"Yên",1,0)) -> 0 | S5: =IF(K5="","",IF(K5>Ngưỡng!$B$6,1,0)) -> 0 | T5: =IF(N5="","",IF(N5>=Ngưỡng!$B$3,1,0)) -> 0 | U5: =IF(I5=5,U4+1,0) -> 0 | V5: =IF(AND(F5<>"",F5>=2),V4+1,0) -> 0 | W5: =IF(O5=0,W4+1,0) -> 0 | X5: =IF(OR(E5="",F5=""),"",ROUND((10*(E5-1)+10*(2-MIN(F5,2)))/60*100,0)) -> 67
A6: P01 | B6: 5 | C6: =IF(B6<=7,1,2) -> 1 | E6: 2 | F6: 1 | G6: 2 | H6: Nghĩ nhiều | I6: 4 | J6: Người | K6: 0.83333333 | L6: 0 | M6: 1 | N6: =IF(OR(E6="",F6="",G6=""),"",10*(E6-1)+10*(G6-1)+10*(2-MIN(F6,2))) -> 30 | O6: =IF(AND(N6<>"",I6<>""),1,0) -> 1 | P6: =IF(N6="","",IF(N6<Ngưỡng!$B$4,1,0)) -> 1 | Q6: =IF(I6="","",IF(I6>=Ngưỡng!$B$5,1,0)) -> 1 | R6: =IF(H6="","",IF(H6<>"Yên",1,0)) -> 1 | S6: =IF(K6="","",IF(K6>Ngưỡng!$B$6,1,0)) -> 0 | T6: =IF(N6="","",IF(N6>=Ngưỡng!$B$3,1,0)) -> 0 | U6: =IF(I6=5,U5+1,0) -> 0 | V6: =IF(AND(F6<>"",F6>=2),V5+1,0) -> 0 | W6: =IF(O6=0,W5+1,0) -> 0 | X6: =IF(OR(E6="",F6=""),"",ROUND((10*(E6-1)+10*(2-MIN(F6,2)))/60*100,0)) -> 33
A7: P01 | B7: 6 | C7: =IF(B7<=7,1,2) -> 1 | E7: 4 | F7: 0 | G7: 3 | H7: Yên | I7: 2 | K7: 0.80208333 | L7: 0.96875 | M7: 1 | N7: =IF(OR(E7="",F7="",G7=""),"",10*(E7-1)+10*(G7-1)+10*(2-MIN(F7,2))) -> 70 | O7: =IF(AND(N7<>"",I7<>""),1,0) -> 1 | P7: =IF(N7="","",IF(N7<Ngưỡng!$B$4,1,0)) -> 0 | Q7: =IF(I7="","",IF(I7>=Ngưỡng!$B$5,1,0)) -> 0 | R7: =IF(H7="","",IF(H7<>"Yên",1,0)) -> 0 | S7: =IF(K7="","",IF(K7>Ngưỡng!$B$6,1,0)) -> 0 | T7: =IF(N7="","",IF(N7>=Ngưỡng!$B$3,1,0)) -> 0 | U7: =IF(I7=5,U6+1,0) -> 0 | V7: =IF(AND(F7<>"",F7>=2),V6+1,0) -> 0 | W7: =IF(O7=0,W6+1,0) -> 0 | X7: =IF(OR(E7="",F7=""),"",ROUND((10*(E7-1)+10*(2-MIN(F7,2)))/60*100,0)) -> 83
A8: P01 | B8: 7 | C8: =IF(B8<=7,1,2) -> 1 | E8: 4 | F8: 0 | G8: 4 | H8: Yên | I8: 2 | K8: 0.79166667 | L8: 0.95833333 | M8: 1 | N8: =IF(OR(E8="",F8="",G8=""),"",10*(E8-1)+10*(G8-1)+10*(2-MIN(F8,2))) -> 80 | O8: =IF(AND(N8<>"",I8<>""),1,0) -> 1 | P8: =IF(N8="","",IF(N8<Ngưỡng!$B$4,1,0)) -> 0 | Q8: =IF(I8="","",IF(I8>=Ngưỡng!$B$5,1,0)) -> 0 | R8: =IF(H8="","",IF(H8<>"Yên",1,0)) -> 0 | S8: =IF(K8="","",IF(K8>Ngưỡng!$B$6,1,0)) -> 0 | T8: =IF(N8="","",IF(N8>=Ngưỡng!$B$3,1,0)) -> 1 | U8: =IF(I8=5,U7+1,0) -> 0 | V8: =IF(AND(F8<>"",F8>=2),V7+1,0) -> 0 | W8: =IF(O8=0,W7+1,0) -> 0 | X8: =IF(OR(E8="",F8=""),"",ROUND((10*(E8-1)+10*(2-MIN(F8,2)))/60*100,0)) -> 83
A9: P01 | B9: 8 | C9: =IF(B9<=7,1,2) -> 2 | E9: 3 | F9: 1 | G9: 3 | H9: Nghĩ nhiều | I9: 4 | J9: Việc | K9: 0.8125 | L9: 0.97916667 | M9: 1 | N9: =IF(OR(E9="",F9="",G9=""),"",10*(E9-1)+10*(G9-1)+10*(2-MIN(F9,2))) -> 50 | O9: =IF(AND(N9<>"",I9<>""),1,0) -> 1 | P9: =IF(N9="","",IF(N9<Ngưỡng!$B$4,1,0)) -> 1 | Q9: =IF(I9="","",IF(I9>=Ngưỡng!$B$5,1,0)) -> 1 | R9: =IF(H9="","",IF(H9<>"Yên",1,0)) -> 1 | S9: =IF(K9="","",IF(K9>Ngưỡng!$B$6,1,0)) -> 0 | T9: =IF(N9="","",IF(N9>=Ngưỡng!$B$3,1,0)) -> 0 | U9: =IF(I9=5,U8+1,0) -> 0 | V9: =IF(AND(F9<>"",F9>=2),V8+1,0) -> 0 | W9: =IF(O9=0,W8+1,0) -> 0 | X9: =IF(OR(E9="",F9=""),"",ROUND((10*(E9-1)+10*(2-MIN(F9,2)))/60*100,0)) -> 50
A10: P01 | B10: 9 | C10: =IF(B10<=7,1,2) -> 2 | E10: 4 | F10: 0 | G10: 4 | H10: Yên | I10: 3 | K10: 0.80555556 | L10: 0.95833333 | M10: 1 | N10: =IF(OR(E10="",F10="",G10=""),"",10*(E10-1)+10*(G10-1)+10*(2-MIN(F10,2))) -> 80 | O10: =IF(AND(N10<>"",I10<>""),1,0) -> 1 | P10: =IF(N10="","",IF(N10<Ngưỡng!$B$4,1,0)) -> 0 | Q10: =IF(I10="","",IF(I10>=Ngưỡng!$B$5,1,0)) -> 0 | R10: =IF(H10="","",IF(H10<>"Yên",1,0)) -> 0 | S10: =IF(K10="","",IF(K10>Ngưỡng!$B$6,1,0)) -> 0 | T10: =IF(N10="","",IF(N10>=Ngưỡng!$B$3,1,0)) -> 1 | U10: =IF(I10=5,U9+1,0) -> 0 | V10: =IF(AND(F10<>"",F10>=2),V9+1,0) -> 0 | W10: =IF(O10=0,W9+1,0) -> 0 | X10: =IF(OR(E10="",F10=""),"",ROUND((10*(E10-1)+10*(2-MIN(F10,2)))/60*100,0)) -> 83
A11: P01 | B11: 10 | C11: =IF(B11<=7,1,2) -> 2 | E11: 5 | F11: 0 | G11: 4 | H11: Yên | I11: 2 | K11: 0.79166667 | L11: 0.94791667 | M11: 1 | N11: =IF(OR(E11="",F11="",G11=""),"",10*(E11-1)+10*(G11-1)+10*(2-MIN(F11,2))) -> 90 | O11: =IF(AND(N11<>"",I11<>""),1,0) -> 1 | P11: =IF(N11="","",IF(N11<Ngưỡng!$B$4,1,0)) -> 0 | Q11: =IF(I11="","",IF(I11>=Ngưỡng!$B$5,1,0)) -> 0 | R11: =IF(H11="","",IF(H11<>"Yên",1,0)) -> 0 | S11: =IF(K11="","",IF(K11>Ngưỡng!$B$6,1,0)) -> 0 | T11: =IF(N11="","",IF(N11>=Ngưỡng!$B$3,1,0)) -> 1 | U11: =IF(I11=5,U10+1,0) -> 0 | V11: =IF(AND(F11<>"",F11>=2),V10+1,0) -> 0 | W11: =IF(O11=0,W10+1,0) -> 0 | X11: =IF(OR(E11="",F11=""),"",ROUND((10*(E11-1)+10*(2-MIN(F11,2)))/60*100,0)) -> 100
A12: P01 | B12: 11 | C12: =IF(B12<=7,1,2) -> 2 | E12: 2 | F12: 2 | G12: 2 | H12: Bực | I12: 5 | J12: Việc | K12: 0.8125 | L12: 0.0069444444 | M12: 1 | N12: =IF(OR(E12="",F12="",G12=""),"",10*(E12-1)+10*(G12-1)+10*(2-MIN(F12,2))) -> 20 | O12: =IF(AND(N12<>"",I12<>""),1,0) -> 1 | P12: =IF(N12="","",IF(N12<Ngưỡng!$B$4,1,0)) -> 1 | Q12: =IF(I12="","",IF(I12>=Ngưỡng!$B$5,1,0)) -> 1 | R12: =IF(H12="","",IF(H12<>"Yên",1,0)) -> 1 | S12: =IF(K12="","",IF(K12>Ngưỡng!$B$6,1,0)) -> 0 | T12: =IF(N12="","",IF(N12>=Ngưỡng!$B$3,1,0)) -> 0 | U12: =IF(I12=5,U11+1,0) -> 1 | V12: =IF(AND(F12<>"",F12>=2),V11+1,0) -> 1 | W12: =IF(O12=0,W11+1,0) -> 0 | X12: =IF(OR(E12="",F12=""),"",ROUND((10*(E12-1)+10*(2-MIN(F12,2)))/60*100,0)) -> 17
A13: P01 | B13: 12 | C13: =IF(B13<=7,1,2) -> 2 | E13: 4 | F13: 0 | G13: 4 | H13: Yên | I13: 2 | K13: 0.79861111 | L13: 0.95833333 | M13: 1 | N13: =IF(OR(E13="",F13="",G13=""),"",10*(E13-1)+10*(G13-1)+10*(2-MIN(F13,2))) -> 80 | O13: =IF(AND(N13<>"",I13<>""),1,0) -> 1 | P13: =IF(N13="","",IF(N13<Ngưỡng!$B$4,1,0)) -> 0 | Q13: =IF(I13="","",IF(I13>=Ngưỡng!$B$5,1,0)) -> 0 | R13: =IF(H13="","",IF(H13<>"Yên",1,0)) -> 0 | S13: =IF(K13="","",IF(K13>Ngưỡng!$B$6,1,0)) -> 0 | T13: =IF(N13="","",IF(N13>=Ngưỡng!$B$3,1,0)) -> 1 | U13: =IF(I13=5,U12+1,0) -> 0 | V13: =IF(AND(F13<>"",F13>=2),V12+1,0) -> 0 | W13: =IF(O13=0,W12+1,0) -> 0 | X13: =IF(OR(E13="",F13=""),"",ROUND((10*(E13-1)+10*(2-MIN(F13,2)))/60*100,0)) -> 83
A14: P01 | B14: 13 | C14: =IF(B14<=7,1,2) -> 2 | E14: 5 | F14: 0 | G14: 4 | H14: Yên | I14: 3 | K14: 0.79166667 | L14: 0.95138889 | M14: 1 | N14: =IF(OR(E14="",F14="",G14=""),"",10*(E14-1)+10*(G14-1)+10*(2-MIN(F14,2))) -> 90 | O14: =IF(AND(N14<>"",I14<>""),1,0) -> 1 | P14: =IF(N14="","",IF(N14<Ngưỡng!$B$4,1,0)) -> 0 | Q14: =IF(I14="","",IF(I14>=Ngưỡng!$B$5,1,0)) -> 0 | R14: =IF(H14="","",IF(H14<>"Yên",1,0)) -> 0 | S14: =IF(K14="","",IF(K14>Ngưỡng!$B$6,1,0)) -> 0 | T14: =IF(N14="","",IF(N14>=Ngưỡng!$B$3,1,0)) -> 1 | U14: =IF(I14=5,U13+1,0) -> 0 | V14: =IF(AND(F14<>"",F14>=2),V13+1,0) -> 0 | W14: =IF(O14=0,W13+1,0) -> 0 | X14: =IF(OR(E14="",F14=""),"",ROUND((10*(E14-1)+10*(2-MIN(F14,2)))/60*100,0)) -> 100
A15: P01 | B15: 14 | C15: =IF(B15<=7,1,2) -> 2 | E15: 4 | F15: 1 | G15: 3 | H15: Nghĩ nhiều | I15: 4 | J15: Việc | K15: 0.8125 | L15: 0.97222222 | M15: 0 | N15: =IF(OR(E15="",F15="",G15=""),"",10*(E15-1)+10*(G15-1)+10*(2-MIN(F15,2))) -> 60 | O15: =IF(AND(N15<>"",I15<>""),1,0) -> 1 | P15: =IF(N15="","",IF(N15<Ngưỡng!$B$4,1,0)) -> 0 | Q15: =IF(I15="","",IF(I15>=Ngưỡng!$B$5,1,0)) -> 1 | R15: =IF(H15="","",IF(H15<>"Yên",1,0)) -> 1 | S15: =IF(K15="","",IF(K15>Ngưỡng!$B$6,1,0)) -> 0 | T15: =IF(N15="","",IF(N15>=Ngưỡng!$B$3,1,0)) -> 0 | U15: =IF(I15=5,U14+1,0) -> 0 | V15: =IF(AND(F15<>"",F15>=2),V14+1,0) -> 0 | W15: =IF(O15=0,W14+1,0) -> 0 | X15: =IF(OR(E15="",F15=""),"",ROUND((10*(E15-1)+10*(2-MIN(F15,2)))/60*100,0)) -> 67
A16: P02 | B16: 1 | C16: =IF(B16<=7,1,2) -> 1 | E16: 3 | F16: 1 | G16: 2 | H16: Yên | I16: 2 | K16: 0.875 | L16: 0.99305556 | N16: =IF(OR(E16="",F16="",G16=""),"",10*(E16-1)+10*(G16-1)+10*(2-MIN(F16,2))) -> 40 | O16: =IF(AND(N16<>"",I16<>""),1,0) -> 1 | P16: =IF(N16="","",IF(N16<Ngưỡng!$B$4,1,0)) -> 1 | Q16: =IF(I16="","",IF(I16>=Ngưỡng!$B$5,1,0)) -> 0 | R16: =IF(H16="","",IF(H16<>"Yên",1,0)) -> 0 | S16: =IF(K16="","",IF(K16>Ngưỡng!$B$6,1,0)) -> 1 | T16: =IF(N16="","",IF(N16>=Ngưỡng!$B$3,1,0)) -> 0 | U16: =IF(I16=5,0+1,0) -> 0 | V16: =IF(AND(F16<>"",F16>=2),0+1,0) -> 0 | W16: =IF(O16=0,0+1,0) -> 0 | X16: =IF(OR(E16="",F16=""),"",ROUND((10*(E16-1)+10*(2-MIN(F16,2)))/60*100,0)) -> 50
A17: P02 | B17: 2 | C17: =IF(B17<=7,1,2) -> 1 | E17: 3 | F17: 1 | G17: 2 | H17: Yên | I17: 3 | K17: 0.86458333 | L17: 0.98958333 | N17: =IF(OR(E17="",F17="",G17=""),"",10*(E17-1)+10*(G17-1)+10*(2-MIN(F17,2))) -> 40 | O17: =IF(AND(N17<>"",I17<>""),1,0) -> 1 | P17: =IF(N17="","",IF(N17<Ngưỡng!$B$4,1,0)) -> 1 | Q17: =IF(I17="","",IF(I17>=Ngưỡng!$B$5,1,0)) -> 0 | R17: =IF(H17="","",IF(H17<>"Yên",1,0)) -> 0 | S17: =IF(K17="","",IF(K17>Ngưỡng!$B$6,1,0)) -> 1 | T17: =IF(N17="","",IF(N17>=Ngưỡng!$B$3,1,0)) -> 0 | U17: =IF(I17=5,U16+1,0) -> 0 | V17: =IF(AND(F17<>"",F17>=2),V16+1,0) -> 0 | W17: =IF(O17=0,W16+1,0) -> 0 | X17: =IF(OR(E17="",F17=""),"",ROUND((10*(E17-1)+10*(2-MIN(F17,2)))/60*100,0)) -> 50
A18: P02 | B18: 3 | C18: =IF(B18<=7,1,2) -> 1 | E18: 2 | F18: 1 | G18: 1 | H18: Yên | I18: 2 | K18: 0.88541667 | L18: 0 | N18: =IF(OR(E18="",F18="",G18=""),"",10*(E18-1)+10*(G18-1)+10*(2-MIN(F18,2))) -> 20 | O18: =IF(AND(N18<>"",I18<>""),1,0) -> 1 | P18: =IF(N18="","",IF(N18<Ngưỡng!$B$4,1,0)) -> 1 | Q18: =IF(I18="","",IF(I18>=Ngưỡng!$B$5,1,0)) -> 0 | R18: =IF(H18="","",IF(H18<>"Yên",1,0)) -> 0 | S18: =IF(K18="","",IF(K18>Ngưỡng!$B$6,1,0)) -> 1 | T18: =IF(N18="","",IF(N18>=Ngưỡng!$B$3,1,0)) -> 0 | U18: =IF(I18=5,U17+1,0) -> 0 | V18: =IF(AND(F18<>"",F18>=2),V17+1,0) -> 0 | W18: =IF(O18=0,W17+1,0) -> 0 | X18: =IF(OR(E18="",F18=""),"",ROUND((10*(E18-1)+10*(2-MIN(F18,2)))/60*100,0)) -> 33
A19: P02 | B19: 4 | C19: =IF(B19<=7,1,2) -> 1 | E19: 3 | F19: 0 | G19: 2 | H19: Yên | I19: 2 | K19: 0.85416667 | L19: 0.97916667 | N19: =IF(OR(E19="",F19="",G19=""),"",10*(E19-1)+10*(G19-1)+10*(2-MIN(F19,2))) -> 50 | O19: =IF(AND(N19<>"",I19<>""),1,0) -> 1 | P19: =IF(N19="","",IF(N19<Ngưỡng!$B$4,1,0)) -> 1 | Q19: =IF(I19="","",IF(I19>=Ngưỡng!$B$5,1,0)) -> 0 | R19: =IF(H19="","",IF(H19<>"Yên",1,0)) -> 0 | S19: =IF(K19="","",IF(K19>Ngưỡng!$B$6,1,0)) -> 1 | T19: =IF(N19="","",IF(N19>=Ngưỡng!$B$3,1,0)) -> 0 | U19: =IF(I19=5,U18+1,0) -> 0 | V19: =IF(AND(F19<>"",F19>=2),V18+1,0) -> 0 | W19: =IF(O19=0,W18+1,0) -> 0 | X19: =IF(OR(E19="",F19=""),"",ROUND((10*(E19-1)+10*(2-MIN(F19,2)))/60*100,0)) -> 67
A20: P02 | B20: 5 | C20: =IF(B20<=7,1,2) -> 1 | E20: 3 | F20: 1 | G20: 2 | H20: Yên | I20: 3 | K20: 0.83333333 | L20: 0.97916667 | M20: 1 | N20: =IF(OR(E20="",F20="",G20=""),"",10*(E20-1)+10*(G20-1)+10*(2-MIN(F20,2))) -> 40 | O20: =IF(AND(N20<>"",I20<>""),1,0) -> 1 | P20: =IF(N20="","",IF(N20<Ngưỡng!$B$4,1,0)) -> 1 | Q20: =IF(I20="","",IF(I20>=Ngưỡng!$B$5,1,0)) -> 0 | R20: =IF(H20="","",IF(H20<>"Yên",1,0)) -> 0 | S20: =IF(K20="","",IF(K20>Ngưỡng!$B$6,1,0)) -> 0 | T20: =IF(N20="","",IF(N20>=Ngưỡng!$B$3,1,0)) -> 0 | U20: =IF(I20=5,U19+1,0) -> 0 | V20: =IF(AND(F20<>"",F20>=2),V19+1,0) -> 0 | W20: =IF(O20=0,W19+1,0) -> 0 | X20: =IF(OR(E20="",F20=""),"",ROUND((10*(E20-1)+10*(2-MIN(F20,2)))/60*100,0)) -> 50
A21: P02 | B21: 6 | C21: =IF(B21<=7,1,2) -> 1 | E21: 4 | F21: 0 | G21: 2 | H21: Yên | I21: 2 | K21: 0.8125 | L21: 0.95833333 | M21: 1 | N21: =IF(OR(E21="",F21="",G21=""),"",10*(E21-1)+10*(G21-1)+10*(2-MIN(F21,2))) -> 60 | O21: =IF(AND(N21<>"",I21<>""),1,0) -> 1 | P21: =IF(N21="","",IF(N21<Ngưỡng!$B$4,1,0)) -> 0 | Q21: =IF(I21="","",IF(I21>=Ngưỡng!$B$5,1,0)) -> 0 | R21: =IF(H21="","",IF(H21<>"Yên",1,0)) -> 0 | S21: =IF(K21="","",IF(K21>Ngưỡng!$B$6,1,0)) -> 0 | T21: =IF(N21="","",IF(N21>=Ngưỡng!$B$3,1,0)) -> 0 | U21: =IF(I21=5,U20+1,0) -> 0 | V21: =IF(AND(F21<>"",F21>=2),V20+1,0) -> 0 | W21: =IF(O21=0,W20+1,0) -> 0 | X21: =IF(OR(E21="",F21=""),"",ROUND((10*(E21-1)+10*(2-MIN(F21,2)))/60*100,0)) -> 83
A22: P02 | B22: 7 | C22: =IF(B22<=7,1,2) -> 1 | E22: 4 | F22: 0 | G22: 2 | H22: Yên | I22: 2 | K22: 0.8125 | L22: 0.95833333 | M22: 1 | N22: =IF(OR(E22="",F22="",G22=""),"",10*(E22-1)+10*(G22-1)+10*(2-MIN(F22,2))) -> 60 | O22: =IF(AND(N22<>"",I22<>""),1,0) -> 1 | P22: =IF(N22="","",IF(N22<Ngưỡng!$B$4,1,0)) -> 0 | Q22: =IF(I22="","",IF(I22>=Ngưỡng!$B$5,1,0)) -> 0 | R22: =IF(H22="","",IF(H22<>"Yên",1,0)) -> 0 | S22: =IF(K22="","",IF(K22>Ngưỡng!$B$6,1,0)) -> 0 | T22: =IF(N22="","",IF(N22>=Ngưỡng!$B$3,1,0)) -> 0 | U22: =IF(I22=5,U21+1,0) -> 0 | V22: =IF(AND(F22<>"",F22>=2),V21+1,0) -> 0 | W22: =IF(O22=0,W21+1,0) -> 0 | X22: =IF(OR(E22="",F22=""),"",ROUND((10*(E22-1)+10*(2-MIN(F22,2)))/60*100,0)) -> 83
A23: P02 | B23: 8 | C23: =IF(B23<=7,1,2) -> 2 | E23: 4 | F23: 0 | G23: 2 | H23: Yên | I23: 3 | K23: 0.80208333 | L23: 0.95833333 | M23: 1 | N23: =IF(OR(E23="",F23="",G23=""),"",10*(E23-1)+10*(G23-1)+10*(2-MIN(F23,2))) -> 60 | O23: =IF(AND(N23<>"",I23<>""),1,0) -> 1 | P23: =IF(N23="","",IF(N23<Ngưỡng!$B$4,1,0)) -> 0 | Q23: =IF(I23="","",IF(I23>=Ngưỡng!$B$5,1,0)) -> 0 | R23: =IF(H23="","",IF(H23<>"Yên",1,0)) -> 0 | S23: =IF(K23="","",IF(K23>Ngưỡng!$B$6,1,0)) -> 0 | T23: =IF(N23="","",IF(N23>=Ngưỡng!$B$3,1,0)) -> 0 | U23: =IF(I23=5,U22+1,0) -> 0 | V23: =IF(AND(F23<>"",F23>=2),V22+1,0) -> 0 | W23: =IF(O23=0,W22+1,0) -> 0 | X23: =IF(OR(E23="",F23=""),"",ROUND((10*(E23-1)+10*(2-MIN(F23,2)))/60*100,0)) -> 83
A24: P02 | B24: 9 | C24: =IF(B24<=7,1,2) -> 2 | E24: 5 | F24: 0 | G24: 3 | H24: Yên | I24: 2 | K24: 0.79166667 | L24: 0.94791667 | M24: 1 | N24: =IF(OR(E24="",F24="",G24=""),"",10*(E24-1)+10*(G24-1)+10*(2-MIN(F24,2))) -> 80 | O24: =IF(AND(N24<>"",I24<>""),1,0) -> 1 | P24: =IF(N24="","",IF(N24<Ngưỡng!$B$4,1,0)) -> 0 | Q24: =IF(I24="","",IF(I24>=Ngưỡng!$B$5,1,0)) -> 0 | R24: =IF(H24="","",IF(H24<>"Yên",1,0)) -> 0 | S24: =IF(K24="","",IF(K24>Ngưỡng!$B$6,1,0)) -> 0 | T24: =IF(N24="","",IF(N24>=Ngưỡng!$B$3,1,0)) -> 1 | U24: =IF(I24=5,U23+1,0) -> 0 | V24: =IF(AND(F24<>"",F24>=2),V23+1,0) -> 0 | W24: =IF(O24=0,W23+1,0) -> 0 | X24: =IF(OR(E24="",F24=""),"",ROUND((10*(E24-1)+10*(2-MIN(F24,2)))/60*100,0)) -> 100
A25: P02 | B25: 10 | C25: =IF(B25<=7,1,2) -> 2 | E25: 4 | F25: 0 | G25: 2 | H25: Yên | I25: 2 | K25: 0.8125 | L25: 0.95833333 | M25: 1 | N25: =IF(OR(E25="",F25="",G25=""),"",10*(E25-1)+10*(G25-1)+10*(2-MIN(F25,2))) -> 60 | O25: =IF(AND(N25<>"",I25<>""),1,0) -> 1 | P25: =IF(N25="","",IF(N25<Ngưỡng!$B$4,1,0)) -> 0 | Q25: =IF(I25="","",IF(I25>=Ngưỡng!$B$5,1,0)) -> 0 | R25: =IF(H25="","",IF(H25<>"Yên",1,0)) -> 0 | S25: =IF(K25="","",IF(K25>Ngưỡng!$B$6,1,0)) -> 0 | T25: =IF(N25="","",IF(N25>=Ngưỡng!$B$3,1,0)) -> 0 | U25: =IF(I25=5,U24+1,0) -> 0 | V25: =IF(AND(F25<>"",F25>=2),V24+1,0) -> 0 | W25: =IF(O25=0,W24+1,0) -> 0 | X25: =IF(OR(E25="",F25=""),"",ROUND((10*(E25-1)+10*(2-MIN(F25,2)))/60*100,0)) -> 83
A26: P02 | B26: 11 | C26: =IF(B26<=7,1,2) -> 2 | E26: 5 | F26: 0 | G26: 2 | H26: Yên | I26: 2 | K26: 0.79166667 | L26: 0.94791667 | M26: 1 | N26: =IF(OR(E26="",F26="",G26=""),"",10*(E26-1)+10*(G26-1)+10*(2-MIN(F26,2))) -> 70 | O26: =IF(AND(N26<>"",I26<>""),1,0) -> 1 | P26: =IF(N26="","",IF(N26<Ngưỡng!$B$4,1,0)) -> 0 | Q26: =IF(I26="","",IF(I26>=Ngưỡng!$B$5,1,0)) -> 0 | R26: =IF(H26="","",IF(H26<>"Yên",1,0)) -> 0 | S26: =IF(K26="","",IF(K26>Ngưỡng!$B$6,1,0)) -> 0 | T26: =IF(N26="","",IF(N26>=Ngưỡng!$B$3,1,0)) -> 0 | U26: =IF(I26=5,U25+1,0) -> 0 | V26: =IF(AND(F26<>"",F26>=2),V25+1,0) -> 0 | W26: =IF(O26=0,W25+1,0) -> 0 | X26: =IF(OR(E26="",F26=""),"",ROUND((10*(E26-1)+10*(2-MIN(F26,2)))/60*100,0)) -> 100
A27: P02 | B27: 12 | C27: =IF(B27<=7,1,2) -> 2 | E27: 4 | F27: 0 | G27: 2 | H27: Yên | I27: 3 | K27: 0.80208333 | L27: 0.95833333 | M27: 1 | N27: =IF(OR(E27="",F27="",G27=""),"",10*(E27-1)+10*(G27-1)+10*(2-MIN(F27,2))) -> 60 | O27: =IF(AND(N27<>"",I27<>""),1,0) -> 1 | P27: =IF(N27="","",IF(N27<Ngưỡng!$B$4,1,0)) -> 0 | Q27: =IF(I27="","",IF(I27>=Ngưỡng!$B$5,1,0)) -> 0 | R27: =IF(H27="","",IF(H27<>"Yên",1,0)) -> 0 | S27: =IF(K27="","",IF(K27>Ngưỡng!$B$6,1,0)) -> 0 | T27: =IF(N27="","",IF(N27>=Ngưỡng!$B$3,1,0)) -> 0 | U27: =IF(I27=5,U26+1,0) -> 0 | V27: =IF(AND(F27<>"",F27>=2),V26+1,0) -> 0 | W27: =IF(O27=0,W26+1,0) -> 0 | X27: =IF(OR(E27="",F27=""),"",ROUND((10*(E27-1)+10*(2-MIN(F27,2)))/60*100,0)) -> 83
A28: P02 | B28: 13 | C28: =IF(B28<=7,1,2) -> 2 | E28: 5 | F28: 0 | G28: 3 | H28: Yên | I28: 2 | K28: 0.79166667 | L28: 0.94444444 | M28: 1 | N28: =IF(OR(E28="",F28="",G28=""),"",10*(E28-1)+10*(G28-1)+10*(2-MIN(F28,2))) -> 80 | O28: =IF(AND(N28<>"",I28<>""),1,0) -> 1 | P28: =IF(N28="","",IF(N28<Ngưỡng!$B$4,1,0)) -> 0 | Q28: =IF(I28="","",IF(I28>=Ngưỡng!$B$5,1,0)) -> 0 | R28: =IF(H28="","",IF(H28<>"Yên",1,0)) -> 0 | S28: =IF(K28="","",IF(K28>Ngưỡng!$B$6,1,0)) -> 0 | T28: =IF(N28="","",IF(N28>=Ngưỡng!$B$3,1,0)) -> 1 | U28: =IF(I28=5,U27+1,0) -> 0 | V28: =IF(AND(F28<>"",F28>=2),V27+1,0) -> 0 | W28: =IF(O28=0,W27+1,0) -> 0 | X28: =IF(OR(E28="",F28=""),"",ROUND((10*(E28-1)+10*(2-MIN(F28,2)))/60*100,0)) -> 100
A29: P02 | B29: 14 | C29: =IF(B29<=7,1,2) -> 2 | E29: 4 | F29: 0 | G29: 2 | H29: Yên | I29: 2 | K29: 0.80555556 | L29: 0.95833333 | M29: 1 | N29: =IF(OR(E29="",F29="",G29=""),"",10*(E29-1)+10*(G29-1)+10*(2-MIN(F29,2))) -> 60 | O29: =IF(AND(N29<>"",I29<>""),1,0) -> 1 | P29: =IF(N29="","",IF(N29<Ngưỡng!$B$4,1,0)) -> 0 | Q29: =IF(I29="","",IF(I29>=Ngưỡng!$B$5,1,0)) -> 0 | R29: =IF(H29="","",IF(H29<>"Yên",1,0)) -> 0 | S29: =IF(K29="","",IF(K29>Ngưỡng!$B$6,1,0)) -> 0 | T29: =IF(N29="","",IF(N29>=Ngưỡng!$B$3,1,0)) -> 0 | U29: =IF(I29=5,U28+1,0) -> 0 | V29: =IF(AND(F29<>"",F29>=2),V28+1,0) -> 0 | W29: =IF(O29=0,W28+1,0) -> 0 | X29: =IF(OR(E29="",F29=""),"",ROUND((10*(E29-1)+10*(2-MIN(F29,2)))/60*100,0)) -> 83
A30: P03 | B30: 1 | C30: =IF(B30<=7,1,2) -> 1 | N30: =IF(OR(E30="",F30="",G30=""),"",10*(E30-1)+10*(G30-1)+10*(2-MIN(F30,2))) | O30: =IF(AND(N30<>"",I30<>""),1,0) -> 0 | P30: =IF(N30="","",IF(N30<Ngưỡng!$B$4,1,0)) | Q30: =IF(I30="","",IF(I30>=Ngưỡng!$B$5,1,0)) | R30: =IF(H30="","",IF(H30<>"Yên",1,0)) | S30: =IF(K30="","",IF(K30>Ngưỡng!$B$6,1,0)) | T30: =IF(N30="","",IF(N30>=Ngưỡng!$B$3,1,0)) | U30: =IF(I30=5,0+1,0) -> 0 | V30: =IF(AND(F30<>"",F30>=2),0+1,0) -> 0 | W30: =IF(O30=0,0+1,0) -> 1 | X30: =IF(OR(E30="",F30=""),"",ROUND((10*(E30-1)+10*(2-MIN(F30,2)))/60*100,0))
A31: P03 | B31: 2 | C31: =IF(B31<=7,1,2) -> 1 | N31: =IF(OR(E31="",F31="",G31=""),"",10*(E31-1)+10*(G31-1)+10*(2-MIN(F31,2))) | O31: =IF(AND(N31<>"",I31<>""),1,0) -> 0 | P31: =IF(N31="","",IF(N31<Ngưỡng!$B$4,1,0)) | Q31: =IF(I31="","",IF(I31>=Ngưỡng!$B$5,1,0)) | R31: =IF(H31="","",IF(H31<>"Yên",1,0)) | S31: =IF(K31="","",IF(K31>Ngưỡng!$B$6,1,0)) | T31: =IF(N31="","",IF(N31>=Ngưỡng!$B$3,1,0)) | U31: =IF(I31=5,U30+1,0) -> 0 | V31: =IF(AND(F31<>"",F31>=2),V30+1,0) -> 0 | W31: =IF(O31=0,W30+1,0) -> 2 | X31: =IF(OR(E31="",F31=""),"",ROUND((10*(E31-1)+10*(2-MIN(F31,2)))/60*100,0))
A32: P03 | B32: 3 | C32: =IF(B32<=7,1,2) -> 1 | N32: =IF(OR(E32="",F32="",G32=""),"",10*(E32-1)+10*(G32-1)+10*(2-MIN(F32,2))) | O32: =IF(AND(N32<>"",I32<>""),1,0) -> 0 | P32: =IF(N32="","",IF(N32<Ngưỡng!$B$4,1,0)) | Q32: =IF(I32="","",IF(I32>=Ngưỡng!$B$5,1,0)) | R32: =IF(H32="","",IF(H32<>"Yên",1,0)) | S32: =IF(K32="","",IF(K32>Ngưỡng!$B$6,1,0)) | T32: =IF(N32="","",IF(N32>=Ngưỡng!$B$3,1,0)) | U32: =IF(I32=5,U31+1,0) -> 0 | V32: =IF(AND(F32<>"",F32>=2),V31+1,0) -> 0 | W32: =IF(O32=0,W31+1,0) -> 3 | X32: =IF(OR(E32="",F32=""),"",ROUND((10*(E32-1)+10*(2-MIN(F32,2)))/60*100,0))
A33: P03 | B33: 4 | C33: =IF(B33<=7,1,2) -> 1 | N33: =IF(OR(E33="",F33="",G33=""),"",10*(E33-1)+10*(G33-1)+10*(2-MIN(F33,2))) | O33: =IF(AND(N33<>"",I33<>""),1,0) -> 0 | P33: =IF(N33="","",IF(N33<Ngưỡng!$B$4,1,0)) | Q33: =IF(I33="","",IF(I33>=Ngưỡng!$B$5,1,0)) | R33: =IF(H33="","",IF(H33<>"Yên",1,0)) | S33: =IF(K33="","",IF(K33>Ngưỡng!$B$6,1,0)) | T33: =IF(N33="","",IF(N33>=Ngưỡng!$B$3,1,0)) | U33: =IF(I33=5,U32+1,0) -> 0 | V33: =IF(AND(F33<>"",F33>=2),V32+1,0) -> 0 | W33: =IF(O33=0,W32+1,0) -> 4 | X33: =IF(OR(E33="",F33=""),"",ROUND((10*(E33-1)+10*(2-MIN(F33,2)))/60*100,0))
A34: P03 | B34: 5 | C34: =IF(B34<=7,1,2) -> 1 | N34: =IF(OR(E34="",F34="",G34=""),"",10*(E34-1)+10*(G34-1)+10*(2-MIN(F34,2))) | O34: =IF(AND(N34<>"",I34<>""),1,0) -> 0 | P34: =IF(N34="","",IF(N34<Ngưỡng!$B$4,1,0)) | Q34: =IF(I34="","",IF(I34>=Ngưỡng!$B$5,1,0)) | R34: =IF(H34="","",IF(H34<>"Yên",1,0)) | S34: =IF(K34="","",IF(K34>Ngưỡng!$B$6,1,0)) | T34: =IF(N34="","",IF(N34>=Ngưỡng!$B$3,1,0)) | U34: =IF(I34=5,U33+1,0) -> 0 | V34: =IF(AND(F34<>"",F34>=2),V33+1,0) -> 0 | W34: =IF(O34=0,W33+1,0) -> 5 | X34: =IF(OR(E34="",F34=""),"",ROUND((10*(E34-1)+10*(2-MIN(F34,2)))/60*100,0))
A35: P03 | B35: 6 | C35: =IF(B35<=7,1,2) -> 1 | N35: =IF(OR(E35="",F35="",G35=""),"",10*(E35-1)+10*(G35-1)+10*(2-MIN(F35,2))) | O35: =IF(AND(N35<>"",I35<>""),1,0) -> 0 | P35: =IF(N35="","",IF(N35<Ngưỡng!$B$4,1,0)) | Q35: =IF(I35="","",IF(I35>=Ngưỡng!$B$5,1,0)) | R35: =IF(H35="","",IF(H35<>"Yên",1,0)) | S35: =IF(K35="","",IF(K35>Ngưỡng!$B$6,1,0)) | T35: =IF(N35="","",IF(N35>=Ngưỡng!$B$3,1,0)) | U35: =IF(I35=5,U34+1,0) -> 0 | V35: =IF(AND(F35<>"",F35>=2),V34+1,0) -> 0 | W35: =IF(O35=0,W34+1,0) -> 6 | X35: =IF(OR(E35="",F35=""),"",ROUND((10*(E35-1)+10*(2-MIN(F35,2)))/60*100,0))
A36: P03 | B36: 7 | C36: =IF(B36<=7,1,2) -> 1 | N36: =IF(OR(E36="",F36="",G36=""),"",10*(E36-1)+10*(G36-1)+10*(2-MIN(F36,2))) | O36: =IF(AND(N36<>"",I36<>""),1,0) -> 0 | P36: =IF(N36="","",IF(N36<Ngưỡng!$B$4,1,0)) | Q36: =IF(I36="","",IF(I36>=Ngưỡng!$B$5,1,0)) | R36: =IF(H36="","",IF(H36<>"Yên",1,0)) | S36: =IF(K36="","",IF(K36>Ngưỡng!$B$6,1,0)) | T36: =IF(N36="","",IF(N36>=Ngưỡng!$B$3,1,0)) | U36: =IF(I36=5,U35+1,0) -> 0 | V36: =IF(AND(F36<>"",F36>=2),V35+1,0) -> 0 | W36: =IF(O36=0,W35+1,0) -> 7 | X36: =IF(OR(E36="",F36=""),"",ROUND((10*(E36-1)+10*(2-MIN(F36,2)))/60*100,0))
A37: P03 | B37: 8 | C37: =IF(B37<=7,1,2) -> 2 | N37: =IF(OR(E37="",F37="",G37=""),"",10*(E37-1)+10*(G37-1)+10*(2-MIN(F37,2))) | O37: =IF(AND(N37<>"",I37<>""),1,0) -> 0 | P37: =IF(N37="","",IF(N37<Ngưỡng!$B$4,1,0)) | Q37: =IF(I37="","",IF(I37>=Ngưỡng!$B$5,1,0)) | R37: =IF(H37="","",IF(H37<>"Yên",1,0)) | S37: =IF(K37="","",IF(K37>Ngưỡng!$B$6,1,0)) | T37: =IF(N37="","",IF(N37>=Ngưỡng!$B$3,1,0)) | U37: =IF(I37=5,U36+1,0) -> 0 | V37: =IF(AND(F37<>"",F37>=2),V36+1,0) -> 0 | W37: =IF(O37=0,W36+1,0) -> 8 | X37: =IF(OR(E37="",F37=""),"",ROUND((10*(E37-1)+10*(2-MIN(F37,2)))/60*100,0))
A38: P03 | B38: 9 | C38: =IF(B38<=7,1,2) -> 2 | N38: =IF(OR(E38="",F38="",G38=""),"",10*(E38-1)+10*(G38-1)+10*(2-MIN(F38,2))) | O38: =IF(AND(N38<>"",I38<>""),1,0) -> 0 | P38: =IF(N38="","",IF(N38<Ngưỡng!$B$4,1,0)) | Q38: =IF(I38="","",IF(I38>=Ngưỡng!$B$5,1,0)) | R38: =IF(H38="","",IF(H38<>"Yên",1,0)) | S38: =IF(K38="","",IF(K38>Ngưỡng!$B$6,1,0)) | T38: =IF(N38="","",IF(N38>=Ngưỡng!$B$3,1,0)) | U38: =IF(I38=5,U37+1,0) -> 0 | V38: =IF(AND(F38<>"",F38>=2),V37+1,0) -> 0 | W38: =IF(O38=0,W37+1,0) -> 9 | X38: =IF(OR(E38="",F38=""),"",ROUND((10*(E38-1)+10*(2-MIN(F38,2)))/60*100,0))
A39: P03 | B39: 10 | C39: =IF(B39<=7,1,2) -> 2 | N39: =IF(OR(E39="",F39="",G39=""),"",10*(E39-1)+10*(G39-1)+10*(2-MIN(F39,2))) | O39: =IF(AND(N39<>"",I39<>""),1,0) -> 0 | P39: =IF(N39="","",IF(N39<Ngưỡng!$B$4,1,0)) | Q39: =IF(I39="","",IF(I39>=Ngưỡng!$B$5,1,0)) | R39: =IF(H39="","",IF(H39<>"Yên",1,0)) | S39: =IF(K39="","",IF(K39>Ngưỡng!$B$6,1,0)) | T39: =IF(N39="","",IF(N39>=Ngưỡng!$B$3,1,0)) | U39: =IF(I39=5,U38+1,0) -> 0 | V39: =IF(AND(F39<>"",F39>=2),V38+1,0) -> 0 | W39: =IF(O39=0,W38+1,0) -> 10 | X39: =IF(OR(E39="",F39=""),"",ROUND((10*(E39-1)+10*(2-MIN(F39,2)))/60*100,0))
A40: P03 | B40: 11 | C40: =IF(B40<=7,1,2) -> 2 | N40: =IF(OR(E40="",F40="",G40=""),"",10*(E40-1)+10*(G40-1)+10*(2-MIN(F40,2))) | O40: =IF(AND(N40<>"",I40<>""),1,0) -> 0 | P40: =IF(N40="","",IF(N40<Ngưỡng!$B$4,1,0)) | Q40: =IF(I40="","",IF(I40>=Ngưỡng!$B$5,1,0)) | R40: =IF(H40="","",IF(H40<>"Yên",1,0)) | S40: =IF(K40="","",IF(K40>Ngưỡng!$B$6,1,0)) | T40: =IF(N40="","",IF(N40>=Ngưỡng!$B$3,1,0)) | U40: =IF(I40=5,U39+1,0) -> 0 | V40: =IF(AND(F40<>"",F40>=2),V39+1,0) -> 0 | W40: =IF(O40=0,W39+1,0) -> 11 | X40: =IF(OR(E40="",F40=""),"",ROUND((10*(E40-1)+10*(2-MIN(F40,2)))/60*100,0))
...

Sheet Tổng kết
A1: Mã người | B1: Ngày đủ dữ liệu | C1: Số ngày căng | D1: Điểm TB tuần 1 | E1: Điểm TB tuần 2 | F1: Chênh T2-T1 | G1: Đêm đạt ngưỡng T2 | H1: Ngủ bám rễ? | I1: Số đêm vỡ | J1: Đêm vỡ khi căng | K1: Tỷ lệ vỡ khi căng | L1: Tỷ lệ vỡ khi yên | M1: Chênh lệch | N1: Tỷ lệ đầu không yên | O1: Số đêm ăn muộn | P1: Tỷ lệ vỡ khi ăn muộn | Q1: Sáng dậy TB tuần 2 | R1: Ngày căng tuần 2 | S1: Nguồn căng chính | T1: KẾT LUẬN NGÀY 15 | U1: LỜI MỜI CỦA AN | V1: Cờ an toàn | W1: n Việc | X1: n Tiền | Y1: n Người | Z1: n Không rõ | AA1: Ngủ thuần TB T2
A2: P01 | B2: =COUNTIFS('Nhật ký'!$A$2:$A$281,$A2,'Nhật ký'!$O$2:$O$281,1) -> 14 | C2: =COUNTIFS('Nhật ký'!$A$2:$A$281,$A2,'Nhật ký'!$Q$2:$Q$281,1) -> 6 | D2: =IFERROR(AVERAGEIFS('Nhật ký'!$N$2:$N$281,'Nhật ký'!$A$2:$A$281,$A2,'Nhật ký'!$C$2:$C$281,1),"") -> 48.571429 | E2: =IFERROR(AVERAGEIFS('Nhật ký'!$N$2:$N$281,'Nhật ký'!$A$2:$A$281,$A2,'Nhật ký'!$C$2:$C$281,2),"") -> 67.142857 | F2: =IF(OR(D2="",E2=""),"",E2-D2) -> 18.571429 | G2: =COUNTIFS('Nhật ký'!$A$2:$A$281,$A2,'Nhật ký'!$T$2:$T$281,1,'Nhật ký'!$C$2:$C$281,2) -> 4 | H2: =IF(F2="","",IF(AND(F2>=Ngưỡng!$B$11,G2>=Ngưỡng!$B$12),"Có","Chưa")) -> Có | I2: =COUNTIFS('Nhật ký'!$A$2:$A$281,$A2,'Nhật ký'!$P$2:$P$281,1) -> 6 | J2: =COUNTIFS('Nhật ký'!$A$2:$A$281,$A2,'Nhật ký'!$P$2:$P$281,1,'Nhật ký'!$Q$2:$Q$281,1) -> 5 | K2: =IFERROR(J2/C2,0) -> 0.83333333 | L2: =IFERROR(COUNTIFS('Nhật ký'!$A$2:$A$281,$A2,'Nhật ký'!$P$2:$P$281,1,'Nhật ký'!$Q$2:$Q$281,0)/COUNTIFS('Nhật ký'!$A$2:$A$281,$A2,'Nhật ký'!$Q$2:$Q$281,0),0) -> 0.125 | M2: =K2-L2 -> 0.70833333 | N2: =IFERROR(COUNTIFS('Nhật ký'!$A$2:$A$281,$A2,'Nhật ký'!$R$2:$R$281,1)/14,0) -> 0.42857143 | O2: =COUNTIFS('Nhật ký'!$A$2:$A$281,$A2,'Nhật ký'!$S$2:$S$281,1) -> 2 | P2: =IFERROR(COUNTIFS('Nhật ký'!$A$2:$A$281,$A2,'Nhật ký'!$P$2:$P$281,1,'Nhật ký'!$S$2:$S$281,1)/O2,0) -> 1 | Q2: =IFERROR(AVERAGEIFS('Nhật ký'!$G$2:$G$281,'Nhật ký'!$A$2:$A$281,$A2,'Nhật ký'!$C$2:$C$281,2),"") -> 3.4285714 | R2: =COUNTIFS('Nhật ký'!$A$2:$A$281,$A2,'Nhật ký'!$Q$2:$Q$281,1,'Nhật ký'!$C$2:$C$281,2) -> 3 | S2: =IF(MAX(W2:Z2)=0,"chưa rõ",INDEX(Ngưỡng!$D$3:$G$3,MATCH(MAX(W2:Z2),W2:Z2,0))) -> Việc | T2: =IF(B2=0,"",IF(B2<Ngưỡng!$B$8,"Chưa đủ dữ liệu: tổng kết ngủ, thêm 7 ngày",IF(H2<>"Có",IF(AND(ISNUMBER(AA2),AA2>=Ngưỡng!$B$27,ISNUMBER(Q2),Q2<Ngưỡng!$B$19),"Mời Hồi sinh lực","Chưa bám rễ: gia hạn 7 ngày"),IF(AND(O2>=Ngưỡng!$B$26,P2>K2),"Gốc tiêu hóa: ở lại Ngủ 7 ngày, dời bữa tối",IF(AND(C2>=Ngưỡng!$B$9,M2>=Ngưỡng!$B$14,K2>=Ngưỡng!$B$15,OR(N2>=Ngưỡng!$B$16,R2>=Ngưỡng!$B$17)),"Mời Xả áp lực",IF(AND(ISNUMBER(Q2),Q2<Ngưỡng!$B$19),"Mời Hồi sinh lực","Vào Cổng Khỏe")))))) -> Mời Xả áp lực | U2: =IF(T2="","",IF(T2="Mời Xả áp lực","14 đêm qua, giấc ngủ của bạn lên từ "&TEXT(D2,"0")&" lên "&TEXT(E2,"0")&" điểm. Nhưng "&J2&" trong "&I2&" đêm vỡ rơi đúng vào ngày bạn chấm căng từ 4, và phần lớn là căng vì "&S2&". Gốc rễ giờ nằm ở ban ngày, mình sang Xả áp lực nhé?",IF(T2="Mời Hồi sinh lực","Giấc ngủ của bạn đã lên "&TEXT(E2,"0")&" điểm, nhưng tuần này bạn vẫn chỉ chấm sáng dậy trung bình "&TEXT(Q2,"0.0")&" trên 5. Ngủ đủ mà vẫn mệt là chuyện của khí. Mình sang Hồi sinh lực nhé?",IF(T2="Vào Cổng Khỏe","Giấc ngủ của bạn đã vững: "&TEXT(E2,"0")&" điểm, "&G2&" đêm đạt ngưỡng tuần này. Cơ thể bạn đã yên. 30 ngày tới mình chỉ chấm điểm sáng, không giao việc nữa.",IF(LEFT(T2,3)="Gốc","Giấc ngủ lên "&TEXT(E2,"0")&" điểm. Nhưng "&O2&" đêm bạn ăn tối sau 20 giờ, và phần lớn đêm vỡ rơi vào những đêm đó. Mình ở lại thêm 7 ngày, chỉ dời bữa tối sớm hơn nhé.",IF(LEFT(T2,4)="Chưa","Giấc ngủ của bạn đang lên từ "&TEXT(D2,"0")&" lên "&TEXT(E2,"0")&" điểm, chưa đủ vững. Mình đi thêm 7 đêm nữa, không vội.","")))))) -> 14 đêm qua, giấc ngủ của bạn lên từ 49 lên 67 điểm. Nhưng 5 trong 6 đêm vỡ rơi đúng vào ngày bạn chấm căng từ 4, và phần lớn là căng vì Việc. Gốc rễ giờ nằm ở ban ngày, mình sang Xả áp lực nhé? | V2: =IF(B2=0,"",IF(SUMPRODUCT(MAX(('Nhật ký'!$A$2:$A$281=$A2)*('Nhật ký'!$U$2:$U$281)))>=Ngưỡng!$B$21,"Căng mức 5 liên tiếp, hỏi riêng; ","")&IF(COUNTIFS('Nhật ký'!$A$2:$A$281,$A2,'Nhật ký'!$H$2:$H$281,"Lo hồi hộp")>=Ngưỡng!$B$22,"Lo hồi hộp nhiều đêm, gợi ý người thật; ","")&IF(SUMPRODUCT(MAX(('Nhật ký'!$A$2:$A$281=$A2)*('Nhật ký'!$V$2:$V$281)))>=Ngưỡng!$B$23,"Tỉnh đêm kéo dài, gợi ý khám; ","")&IF(SUMPRODUCT(MAX(('Nhật ký'!$A$2:$A$281=$A2)*('Nhật ký'!$W$2:$W$281)))>=Ngưỡng!$B$24,"Thiếu dữ liệu nhiều ngày, hỏi một câu; ","")) | W2: =COUNTIFS('Nhật ký'!$A$2:$A$281,$A2,'Nhật ký'!$J$2:$J$281,"Việc",'Nhật ký'!$Q$2:$Q$281,1) -> 5 | X2: =COUNTIFS('Nhật ký'!$A$2:$A$281,$A2,'Nhật ký'!$J$2:$J$281,"Tiền",'Nhật ký'!$Q$2:$Q$281,1) -> 0 | Y2: =COUNTIFS('Nhật ký'!$A$2:$A$281,$A2,'Nhật ký'!$J$2:$J$281,"Người",'Nhật ký'!$Q$2:$Q$281,1) -> 1 | Z2: =COUNTIFS('Nhật ký'!$A$2:$A$281,$A2,'Nhật ký'!$J$2:$J$281,"Không rõ",'Nhật ký'!$Q$2:$Q$281,1) -> 0 | AA2: =IFERROR(AVERAGEIFS('Nhật ký'!$X$2:$X$281,'Nhật ký'!$A$2:$A$281,$A2,'Nhật ký'!$C$2:$C$281,2),"") -> 71.428571
A3: P02 | B3: =COUNTIFS('Nhật ký'!$A$2:$A$281,$A3,'Nhật ký'!$O$2:$O$281,1) -> 14 | C3: =COUNTIFS('Nhật ký'!$A$2:$A$281,$A3,'Nhật ký'!$Q$2:$Q$281,1) -> 0 | D3: =IFERROR(AVERAGEIFS('Nhật ký'!$N$2:$N$281,'Nhật ký'!$A$2:$A$281,$A3,'Nhật ký'!$C$2:$C$281,1),"") -> 44.285714 | E3: =IFERROR(AVERAGEIFS('Nhật ký'!$N$2:$N$281,'Nhật ký'!$A$2:$A$281,$A3,'Nhật ký'!$C$2:$C$281,2),"") -> 67.142857 | F3: =IF(OR(D3="",E3=""),"",E3-D3) -> 22.857143 | G3: =COUNTIFS('Nhật ký'!$A$2:$A$281,$A3,'Nhật ký'!$T$2:$T$281,1,'Nhật ký'!$C$2:$C$281,2) -> 2 | H3: =IF(F3="","",IF(AND(F3>=Ngưỡng!$B$11,G3>=Ngưỡng!$B$12),"Có","Chưa")) -> Chưa | I3: =COUNTIFS('Nhật ký'!$A$2:$A$281,$A3,'Nhật ký'!$P$2:$P$281,1) -> 5 | J3: =COUNTIFS('Nhật ký'!$A$2:$A$281,$A3,'Nhật ký'!$P$2:$P$281,1,'Nhật ký'!$Q$2:$Q$281,1) -> 0 | K3: =IFERROR(J3/C3,0) -> 0 | L3: =IFERROR(COUNTIFS('Nhật ký'!$A$2:$A$281,$A3,'Nhật ký'!$P$2:$P$281,1,'Nhật ký'!$Q$2:$Q$281,0)/COUNTIFS('Nhật ký'!$A$2:$A$281,$A3,'Nhật ký'!$Q$2:$Q$281,0),0) -> 0.35714286 | M3: =K3-L3 -> -0.35714286 | N3: =IFERROR(COUNTIFS('Nhật ký'!$A$2:$A$281,$A3,'Nhật ký'!$R$2:$R$281,1)/14,0) -> 0 | O3: =COUNTIFS('Nhật ký'!$A$2:$A$281,$A3,'Nhật ký'!$S$2:$S$281,1) -> 4 | P3: =IFERROR(COUNTIFS('Nhật ký'!$A$2:$A$281,$A3,'Nhật ký'!$P$2:$P$281,1,'Nhật ký'!$S$2:$S$281,1)/O3,0) -> 1 | Q3: =IFERROR(AVERAGEIFS('Nhật ký'!$G$2:$G$281,'Nhật ký'!$A$2:$A$281,$A3,'Nhật ký'!$C$2:$C$281,2),"") -> 2.2857143 | R3: =COUNTIFS('Nhật ký'!$A$2:$A$281,$A3,'Nhật ký'!$Q$2:$Q$281,1,'Nhật ký'!$C$2:$C$281,2) -> 0 | S3: =IF(MAX(W3:Z3)=0,"chưa rõ",INDEX(Ngưỡng!$D$3:$G$3,MATCH(MAX(W3:Z3),W3:Z3,0))) -> chưa rõ | T3: =IF(B3=0,"",IF(B3<Ngưỡng!$B$8,"Chưa đủ dữ liệu: tổng kết ngủ, thêm 7 ngày",IF(H3<>"Có",IF(AND(ISNUMBER(AA3),AA3>=Ngưỡng!$B$27,ISNUMBER(Q3),Q3<Ngưỡng!$B$19),"Mời Hồi sinh lực","Chưa bám rễ: gia hạn 7 ngày"),IF(AND(O3>=Ngưỡng!$B$26,P3>K3),"Gốc tiêu hóa: ở lại Ngủ 7 ngày, dời bữa tối",IF(AND(C3>=Ngưỡng!$B$9,M3>=Ngưỡng!$B$14,K3>=Ngưỡng!$B$15,OR(N3>=Ngưỡng!$B$16,R3>=Ngưỡng!$B$17)),"Mời Xả áp lực",IF(AND(ISNUMBER(Q3),Q3<Ngưỡng!$B$19),"Mời Hồi sinh lực","Vào Cổng Khỏe")))))) -> Mời Hồi sinh lực | U3: =IF(T3="","",IF(T3="Mời Xả áp lực","14 đêm qua, giấc ngủ của bạn lên từ "&TEXT(D3,"0")&" lên "&TEXT(E3,"0")&" điểm. Nhưng "&J3&" trong "&I3&" đêm vỡ rơi đúng vào ngày bạn chấm căng từ 4, và phần lớn là căng vì "&S3&". Gốc rễ giờ nằm ở ban ngày, mình sang Xả áp lực nhé?",IF(T3="Mời Hồi sinh lực","Giấc ngủ của bạn đã lên "&TEXT(E3,"0")&" điểm, nhưng tuần này bạn vẫn chỉ chấm sáng dậy trung bình "&TEXT(Q3,"0.0")&" trên 5. Ngủ đủ mà vẫn mệt là chuyện của khí. Mình sang Hồi sinh lực nhé?",IF(T3="Vào Cổng Khỏe","Giấc ngủ của bạn đã vững: "&TEXT(E3,"0")&" điểm, "&G3&" đêm đạt ngưỡng tuần này. Cơ thể bạn đã yên. 30 ngày tới mình chỉ chấm điểm sáng, không giao việc nữa.",IF(LEFT(T3,3)="Gốc","Giấc ngủ lên "&TEXT(E3,"0")&" điểm. Nhưng "&O3&" đêm bạn ăn tối sau 20 giờ, và phần lớn đêm vỡ rơi vào những đêm đó. Mình ở lại thêm 7 ngày, chỉ dời bữa tối sớm hơn nhé.",IF(LEFT(T3,4)="Chưa","Giấc ngủ của bạn đang lên từ "&TEXT(D3,"0")&" lên "&TEXT(E3,"0")&" điểm, chưa đủ vững. Mình đi thêm 7 đêm nữa, không vội.","")))))) -> Giấc ngủ của bạn đã lên 67 điểm, nhưng tuần này bạn vẫn chỉ chấm sáng dậy trung bình 2.3 trên 5. Ngủ đủ mà vẫn mệt là chuyện của khí. Mình sang Hồi sinh lực nhé? | V3: =IF(B3=0,"",IF(SUMPRODUCT(MAX(('Nhật ký'!$A$2:$A$281=$A3)*('Nhật ký'!$U$2:$U$281)))>=Ngưỡng!$B$21,"Căng mức 5 liên tiếp, hỏi riêng; ","")&IF(COUNTIFS('Nhật ký'!$A$2:$A$281,$A3,'Nhật ký'!$H$2:$H$281,"Lo hồi hộp")>=Ngưỡng!$B$22,"Lo hồi hộp nhiều đêm, gợi ý người thật; ","")&IF(SUMPRODUCT(MAX(('Nhật ký'!$A$2:$A$281=$A3)*('Nhật ký'!$V$2:$V$281)))>=Ngưỡng!$B$23,"Tỉnh đêm kéo dài, gợi ý khám; ","")&IF(SUMPRODUCT(MAX(('Nhật ký'!$A$2:$A$281=$A3)*('Nhật ký'!$W$2:$W$281)))>=Ngưỡng!$B$24,"Thiếu dữ liệu nhiều ngày, hỏi một câu; ","")) | W3: =COUNTIFS('Nhật ký'!$A$2:$A$281,$A3,'Nhật ký'!$J$2:$J$281,"Việc",'Nhật ký'!$Q$2:$Q$281,1) -> 0 | X3: =COUNTIFS('Nhật ký'!$A$2:$A$281,$A3,'Nhật ký'!$J$2:$J$281,"Tiền",'Nhật ký'!$Q$2:$Q$281,1) -> 0 | Y3: =COUNTIFS('Nhật ký'!$A$2:$A$281,$A3,'Nhật ký'!$J$2:$J$281,"Người",'Nhật ký'!$Q$2:$Q$281,1) -> 0 | Z3: =COUNTIFS('Nhật ký'!$A$2:$A$281,$A3,'Nhật ký'!$J$2:$J$281,"Không rõ",'Nhật ký'!$Q$2:$Q$281,1) -> 0 | AA3: =IFERROR(AVERAGEIFS('Nhật ký'!$X$2:$X$281,'Nhật ký'!$A$2:$A$281,$A3,'Nhật ký'!$C$2:$C$281,2),"") -> 90.285714
A4: P03 | B4: =COUNTIFS('Nhật ký'!$A$2:$A$281,$A4,'Nhật ký'!$O$2:$O$281,1) -> 0 | C4: =COUNTIFS('Nhật ký'!$A$2:$A$281,$A4,'Nhật ký'!$Q$2:$Q$281,1) -> 0 | D4: =IFERROR(AVERAGEIFS('Nhật ký'!$N$2:$N$281,'Nhật ký'!$A$2:$A$281,$A4,'Nhật ký'!$C$2:$C$281,1),"") | E4: =IFERROR(AVERAGEIFS('Nhật ký'!$N$2:$N$281,'Nhật ký'!$A$2:$A$281,$A4,'Nhật ký'!$C$2:$C$281,2),"") | F4: =IF(OR(D4="",E4=""),"",E4-D4) | G4: =COUNTIFS('Nhật ký'!$A$2:$A$281,$A4,'Nhật ký'!$T$2:$T$281,1,'Nhật ký'!$C$2:$C$281,2) -> 0 | H4: =IF(F4="","",IF(AND(F4>=Ngưỡng!$B$11,G4>=Ngưỡng!$B$12),"Có","Chưa")) | I4: =COUNTIFS('Nhật ký'!$A$2:$A$281,$A4,'Nhật ký'!$P$2:$P$281,1) -> 0 | J4: =COUNTIFS('Nhật ký'!$A$2:$A$281,$A4,'Nhật ký'!$P$2:$P$281,1,'Nhật ký'!$Q$2:$Q$281,1) -> 0 | K4: =IFERROR(J4/C4,0) -> 0 | L4: =IFERROR(COUNTIFS('Nhật ký'!$A$2:$A$281,$A4,'Nhật ký'!$P$2:$P$281,1,'Nhật ký'!$Q$2:$Q$281,0)/COUNTIFS('Nhật ký'!$A$2:$A$281,$A4,'Nhật ký'!$Q$2:$Q$281,0),0) -> 0 | M4: =K4-L4 -> 0 | N4: =IFERROR(COUNTIFS('Nhật ký'!$A$2:$A$281,$A4,'Nhật ký'!$R$2:$R$281,1)/14,0) -> 0 | O4: =COUNTIFS('Nhật ký'!$A$2:$A$281,$A4,'Nhật ký'!$S$2:$S$281,1) -> 0 | P4: =IFERROR(COUNTIFS('Nhật ký'!$A$2:$A$281,$A4,'Nhật ký'!$P$2:$P$281,1,'Nhật ký'!$S$2:$S$281,1)/O4,0) -> 0 | Q4: =IFERROR(AVERAGEIFS('Nhật ký'!$G$2:$G$281,'Nhật ký'!$A$2:$A$281,$A4,'Nhật ký'!$C$2:$C$281,2),"") | R4: =COUNTIFS('Nhật ký'!$A$2:$A$281,$A4,'Nhật ký'!$Q$2:$Q$281,1,'Nhật ký'!$C$2:$C$281,2) -> 0 | S4: =IF(MAX(W4:Z4)=0,"chưa rõ",INDEX(Ngưỡng!$D$3:$G$3,MATCH(MAX(W4:Z4),W4:Z4,0))) -> chưa rõ | T4: =IF(B4=0,"",IF(B4<Ngưỡng!$B$8,"Chưa đủ dữ liệu: tổng kết ngủ, thêm 7 ngày",IF(H4<>"Có",IF(AND(ISNUMBER(AA4),AA4>=Ngưỡng!$B$27,ISNUMBER(Q4),Q4<Ngưỡng!$B$19),"Mời Hồi sinh lực","Chưa bám rễ: gia hạn 7 ngày"),IF(AND(O4>=Ngưỡng!$B$26,P4>K4),"Gốc tiêu hóa: ở lại Ngủ 7 ngày, dời bữa tối",IF(AND(C4>=Ngưỡng!$B$9,M4>=Ngưỡng!$B$14,K4>=Ngưỡng!$B$15,OR(N4>=Ngưỡng!$B$16,R4>=Ngưỡng!$B$17)),"Mời Xả áp lực",IF(AND(ISNUMBER(Q4),Q4<Ngưỡng!$B$19),"Mời Hồi sinh lực","Vào Cổng Khỏe")))))) | U4: =IF(T4="","",IF(T4="Mời Xả áp lực","14 đêm qua, giấc ngủ của bạn lên từ "&TEXT(D4,"0")&" lên "&TEXT(E4,"0")&" điểm. Nhưng "&J4&" trong "&I4&" đêm vỡ rơi đúng vào ngày bạn chấm căng từ 4, và phần lớn là căng vì "&S4&". Gốc rễ giờ nằm ở ban ngày, mình sang Xả áp lực nhé?",IF(T4="Mời Hồi sinh lực","Giấc ngủ của bạn đã lên "&TEXT(E4,"0")&" điểm, nhưng tuần này bạn vẫn chỉ chấm sáng dậy trung bình "&TEXT(Q4,"0.0")&" trên 5. Ngủ đủ mà vẫn mệt là chuyện của khí. Mình sang Hồi sinh lực nhé?",IF(T4="Vào Cổng Khỏe","Giấc ngủ của bạn đã vững: "&TEXT(E4,"0")&" điểm, "&G4&" đêm đạt ngưỡng tuần này. Cơ thể bạn đã yên. 30 ngày tới mình chỉ chấm điểm sáng, không giao việc nữa.",IF(LEFT(T4,3)="Gốc","Giấc ngủ lên "&TEXT(E4,"0")&" điểm. Nhưng "&O4&" đêm bạn ăn tối sau 20 giờ, và phần lớn đêm vỡ rơi vào những đêm đó. Mình ở lại thêm 7 ngày, chỉ dời bữa tối sớm hơn nhé.",IF(LEFT(T4,4)="Chưa","Giấc ngủ của bạn đang lên từ "&TEXT(D4,"0")&" lên "&TEXT(E4,"0")&" điểm, chưa đủ vững. Mình đi thêm 7 đêm nữa, không vội.","")))))) | V4: =IF(B4=0,"",IF(SUMPRODUCT(MAX(('Nhật ký'!$A$2:$A$281=$A4)*('Nhật ký'!$U$2:$U$281)))>=Ngưỡng!$B$21,"Căng mức 5 liên tiếp, hỏi riêng; ","")&IF(COUNTIFS('Nhật ký'!$A$2:$A$281,$A4,'Nhật ký'!$H$2:$H$281,"Lo hồi hộp")>=Ngưỡng!$B$22,"Lo hồi hộp nhiều đêm, gợi ý người thật; ","")&IF(SUMPRODUCT(MAX(('Nhật ký'!$A$2:$A$281=$A4)*('Nhật ký'!$V$2:$V$281)))>=Ngưỡng!$B$23,"Tỉnh đêm kéo dài, gợi ý khám; ","")&IF(SUMPRODUCT(MAX(('Nhật ký'!$A$2:$A$281=$A4)*('Nhật ký'!$W$2:$W$281)))>=Ngưỡng!$B$24,"Thiếu dữ liệu nhiều ngày, hỏi một câu; ","")) | W4: =COUNTIFS('Nhật ký'!$A$2:$A$281,$A4,'Nhật ký'!$J$2:$J$281,"Việc",'Nhật ký'!$Q$2:$Q$281,1) -> 0 | X4: =COUNTIFS('Nhật ký'!$A$2:$A$281,$A4,'Nhật ký'!$J$2:$J$281,"Tiền",'Nhật ký'!$Q$2:$Q$281,1) -> 0 | Y4: =COUNTIFS('Nhật ký'!$A$2:$A$281,$A4,'Nhật ký'!$J$2:$J$281,"Người",'Nhật ký'!$Q$2:$Q$281,1) -> 0 | Z4: =COUNTIFS('Nhật ký'!$A$2:$A$281,$A4,'Nhật ký'!$J$2:$J$281,"Không rõ",'Nhật ký'!$Q$2:$Q$281,1) -> 0 | AA4: =IFERROR(AVERAGEIFS('Nhật ký'!$X$2:$X$281,'Nhật ký'!$A$2:$A$281,$A4,'Nhật ký'!$C$2:$C$281,2),"")
A5: P04 | B5: =COUNTIFS('Nhật ký'!$A$2:$A$281,$A5,'Nhật ký'!$O$2:$O$281,1) -> 0 | C5: =COUNTIFS('Nhật ký'!$A$2:$A$281,$A5,'Nhật ký'!$Q$2:$Q$281,1) -> 0 | D5: =IFERROR(AVERAGEIFS('Nhật ký'!$N$2:$N$281,'Nhật ký'!$A$2:$A$281,$A5,'Nhật ký'!$C$2:$C$281,1),"") | E5: =IFERROR(AVERAGEIFS('Nhật ký'!$N$2:$N$281,'Nhật ký'!$A$2:$A$281,$A5,'Nhật ký'!$C$2:$C$281,2),"") | F5: =IF(OR(D5="",E5=""),"",E5-D5) | G5: =COUNTIFS('Nhật ký'!$A$2:$A$281,$A5,'Nhật ký'!$T$2:$T$281,1,'Nhật ký'!$C$2:$C$281,2) -> 0 | H5: =IF(F5="","",IF(AND(F5>=Ngưỡng!$B$11,G5>=Ngưỡng!$B$12),"Có","Chưa")) | I5: =COUNTIFS('Nhật ký'!$A$2:$A$281,$A5,'Nhật ký'!$P$2:$P$281,1) -> 0 | J5: =COUNTIFS('Nhật ký'!$A$2:$A$281,$A5,'Nhật ký'!$P$2:$P$281,1,'Nhật ký'!$Q$2:$Q$281,1) -> 0 | K5: =IFERROR(J5/C5,0) -> 0 | L5: =IFERROR(COUNTIFS('Nhật ký'!$A$2:$A$281,$A5,'Nhật ký'!$P$2:$P$281,1,'Nhật ký'!$Q$2:$Q$281,0)/COUNTIFS('Nhật ký'!$A$2:$A$281,$A5,'Nhật ký'!$Q$2:$Q$281,0),0) -> 0 | M5: =K5-L5 -> 0 | N5: =IFERROR(COUNTIFS('Nhật ký'!$A$2:$A$281,$A5,'Nhật ký'!$R$2:$R$281,1)/14,0) -> 0 | O5: =COUNTIFS('Nhật ký'!$A$2:$A$281,$A5,'Nhật ký'!$S$2:$S$281,1) -> 0 | P5: =IFERROR(COUNTIFS('Nhật ký'!$A$2:$A$281,$A5,'Nhật ký'!$P$2:$P$281,1,'Nhật ký'!$S$2:$S$281,1)/O5,0) -> 0 | Q5: =IFERROR(AVERAGEIFS('Nhật ký'!$G$2:$G$281,'Nhật ký'!$A$2:$A$281,$A5,'Nhật ký'!$C$2:$C$281,2),"") | R5: =COUNTIFS('Nhật ký'!$A$2:$A$281,$A5,'Nhật ký'!$Q$2:$Q$281,1,'Nhật ký'!$C$2:$C$281,2) -> 0 | S5: =IF(MAX(W5:Z5)=0,"chưa rõ",INDEX(Ngưỡng!$D$3:$G$3,MATCH(MAX(W5:Z5),W5:Z5,0))) -> chưa rõ | T5: =IF(B5=0,"",IF(B5<Ngưỡng!$B$8,"Chưa đủ dữ liệu: tổng kết ngủ, thêm 7 ngày",IF(H5<>"Có",IF(AND(ISNUMBER(AA5),AA5>=Ngưỡng!$B$27,ISNUMBER(Q5),Q5<Ngưỡng!$B$19),"Mời Hồi sinh lực","Chưa bám rễ: gia hạn 7 ngày"),IF(AND(O5>=Ngưỡng!$B$26,P5>K5),"Gốc tiêu hóa: ở lại Ngủ 7 ngày, dời bữa tối",IF(AND(C5>=Ngưỡng!$B$9,M5>=Ngưỡng!$B$14,K5>=Ngưỡng!$B$15,OR(N5>=Ngưỡng!$B$16,R5>=Ngưỡng!$B$17)),"Mời Xả áp lực",IF(AND(ISNUMBER(Q5),Q5<Ngưỡng!$B$19),"Mời Hồi sinh lực","Vào Cổng Khỏe")))))) | U5: =IF(T5="","",IF(T5="Mời Xả áp lực","14 đêm qua, giấc ngủ của bạn lên từ "&TEXT(D5,"0")&" lên "&TEXT(E5,"0")&" điểm. Nhưng "&J5&" trong "&I5&" đêm vỡ rơi đúng vào ngày bạn chấm căng từ 4, và phần lớn là căng vì "&S5&". Gốc rễ giờ nằm ở ban ngày, mình sang Xả áp lực nhé?",IF(T5="Mời Hồi sinh lực","Giấc ngủ của bạn đã lên "&TEXT(E5,"0")&" điểm, nhưng tuần này bạn vẫn chỉ chấm sáng dậy trung bình "&TEXT(Q5,"0.0")&" trên 5. Ngủ đủ mà vẫn mệt là chuyện của khí. Mình sang Hồi sinh lực nhé?",IF(T5="Vào Cổng Khỏe","Giấc ngủ của bạn đã vững: "&TEXT(E5,"0")&" điểm, "&G5&" đêm đạt ngưỡng tuần này. Cơ thể bạn đã yên. 30 ngày tới mình chỉ chấm điểm sáng, không giao việc nữa.",IF(LEFT(T5,3)="Gốc","Giấc ngủ lên "&TEXT(E5,"0")&" điểm. Nhưng "&O5&" đêm bạn ăn tối sau 20 giờ, và phần lớn đêm vỡ rơi vào những đêm đó. Mình ở lại thêm 7 ngày, chỉ dời bữa tối sớm hơn nhé.",IF(LEFT(T5,4)="Chưa","Giấc ngủ của bạn đang lên từ "&TEXT(D5,"0")&" lên "&TEXT(E5,"0")&" điểm, chưa đủ vững. Mình đi thêm 7 đêm nữa, không vội.","")))))) | V5: =IF(B5=0,"",IF(SUMPRODUCT(MAX(('Nhật ký'!$A$2:$A$281=$A5)*('Nhật ký'!$U$2:$U$281)))>=Ngưỡng!$B$21,"Căng mức 5 liên tiếp, hỏi riêng; ","")&IF(COUNTIFS('Nhật ký'!$A$2:$A$281,$A5,'Nhật ký'!$H$2:$H$281,"Lo hồi hộp")>=Ngưỡng!$B$22,"Lo hồi hộp nhiều đêm, gợi ý người thật; ","")&IF(SUMPRODUCT(MAX(('Nhật ký'!$A$2:$A$281=$A5)*('Nhật ký'!$V$2:$V$281)))>=Ngưỡng!$B$23,"Tỉnh đêm kéo dài, gợi ý khám; ","")&IF(SUMPRODUCT(MAX(('Nhật ký'!$A$2:$A$281=$A5)*('Nhật ký'!$W$2:$W$281)))>=Ngưỡng!$B$24,"Thiếu dữ liệu nhiều ngày, hỏi một câu; ","")) | W5: =COUNTIFS('Nhật ký'!$A$2:$A$281,$A5,'Nhật ký'!$J$2:$J$281,"Việc",'Nhật ký'!$Q$2:$Q$281,1) -> 0 | X5: =COUNTIFS('Nhật ký'!$A$2:$A$281,$A5,'Nhật ký'!$J$2:$J$281,"Tiền",'Nhật ký'!$Q$2:$Q$281,1) -> 0 | Y5: =COUNTIFS('Nhật ký'!$A$2:$A$281,$A5,'Nhật ký'!$J$2:$J$281,"Người",'Nhật ký'!$Q$2:$Q$281,1) -> 0 | Z5: =COUNTIFS('Nhật ký'!$A$2:$A$281,$A5,'Nhật ký'!$J$2:$J$281,"Không rõ",'Nhật ký'!$Q$2:$Q$281,1) -> 0 | AA5: =IFERROR(AVERAGEIFS('Nhật ký'!$X$2:$X$281,'Nhật ký'!$A$2:$A$281,$A5,'Nhật ký'!$C$2:$C$281,2),"")
A6: P05 | B6: =COUNTIFS('Nhật ký'!$A$2:$A$281,$A6,'Nhật ký'!$O$2:$O$281,1) -> 0 | C6: =COUNTIFS('Nhật ký'!$A$2:$A$281,$A6,'Nhật ký'!$Q$2:$Q$281,1) -> 0 | D6: =IFERROR(AVERAGEIFS('Nhật ký'!$N$2:$N$281,'Nhật ký'!$A$2:$A$281,$A6,'Nhật ký'!$C$2:$C$281,1),"") | E6: =IFERROR(AVERAGEIFS('Nhật ký'!$N$2:$N$281,'Nhật ký'!$A$2:$A$281,$A6,'Nhật ký'!$C$2:$C$281,2),"") | F6: =IF(OR(D6="",E6=""),"",E6-D6) | G6: =COUNTIFS('Nhật ký'!$A$2:$A$281,$A6,'Nhật ký'!$T$2:$T$281,1,'Nhật ký'!$C$2:$C$281,2) -> 0 | H6: =IF(F6="","",IF(AND(F6>=Ngưỡng!$B$11,G6>=Ngưỡng!$B$12),"Có","Chưa")) | I6: =COUNTIFS('Nhật ký'!$A$2:$A$281,$A6,'Nhật ký'!$P$2:$P$281,1) -> 0 | J6: =COUNTIFS('Nhật ký'!$A$2:$A$281,$A6,'Nhật ký'!$P$2:$P$281,1,'Nhật ký'!$Q$2:$Q$281,1) -> 0 | K6: =IFERROR(J6/C6,0) -> 0 | L6: =IFERROR(COUNTIFS('Nhật ký'!$A$2:$A$281,$A6,'Nhật ký'!$P$2:$P$281,1,'Nhật ký'!$Q$2:$Q$281,0)/COUNTIFS('Nhật ký'!$A$2:$A$281,$A6,'Nhật ký'!$Q$2:$Q$281,0),0) -> 0 | M6: =K6-L6 -> 0 | N6: =IFERROR(COUNTIFS('Nhật ký'!$A$2:$A$281,$A6,'Nhật ký'!$R$2:$R$281,1)/14,0) -> 0 | O6: =COUNTIFS('Nhật ký'!$A$2:$A$281,$A6,'Nhật ký'!$S$2:$S$281,1) -> 0 | P6: =IFERROR(COUNTIFS('Nhật ký'!$A$2:$A$281,$A6,'Nhật ký'!$P$2:$P$281,1,'Nhật ký'!$S$2:$S$281,1)/O6,0) -> 0 | Q6: =IFERROR(AVERAGEIFS('Nhật ký'!$G$2:$G$281,'Nhật ký'!$A$2:$A$281,$A6,'Nhật ký'!$C$2:$C$281,2),"") | R6: =COUNTIFS('Nhật ký'!$A$2:$A$281,$A6,'Nhật ký'!$Q$2:$Q$281,1,'Nhật ký'!$C$2:$C$281,2) -> 0 | S6: =IF(MAX(W6:Z6)=0,"chưa rõ",INDEX(Ngưỡng!$D$3:$G$3,MATCH(MAX(W6:Z6),W6:Z6,0))) -> chưa rõ | T6: =IF(B6=0,"",IF(B6<Ngưỡng!$B$8,"Chưa đủ dữ liệu: tổng kết ngủ, thêm 7 ngày",IF(H6<>"Có",IF(AND(ISNUMBER(AA6),AA6>=Ngưỡng!$B$27,ISNUMBER(Q6),Q6<Ngưỡng!$B$19),"Mời Hồi sinh lực","Chưa bám rễ: gia hạn 7 ngày"),IF(AND(O6>=Ngưỡng!$B$26,P6>K6),"Gốc tiêu hóa: ở lại Ngủ 7 ngày, dời bữa tối",IF(AND(C6>=Ngưỡng!$B$9,M6>=Ngưỡng!$B$14,K6>=Ngưỡng!$B$15,OR(N6>=Ngưỡng!$B$16,R6>=Ngưỡng!$B$17)),"Mời Xả áp lực",IF(AND(ISNUMBER(Q6),Q6<Ngưỡng!$B$19),"Mời Hồi sinh lực","Vào Cổng Khỏe")))))) | U6: =IF(T6="","",IF(T6="Mời Xả áp lực","14 đêm qua, giấc ngủ của bạn lên từ "&TEXT(D6,"0")&" lên "&TEXT(E6,"0")&" điểm. Nhưng "&J6&" trong "&I6&" đêm vỡ rơi đúng vào ngày bạn chấm căng từ 4, và phần lớn là căng vì "&S6&". Gốc rễ giờ nằm ở ban ngày, mình sang Xả áp lực nhé?",IF(T6="Mời Hồi sinh lực","Giấc ngủ của bạn đã lên "&TEXT(E6,"0")&" điểm, nhưng tuần này bạn vẫn chỉ chấm sáng dậy trung bình "&TEXT(Q6,"0.0")&" trên 5. Ngủ đủ mà vẫn mệt là chuyện của khí. Mình sang Hồi sinh lực nhé?",IF(T6="Vào Cổng Khỏe","Giấc ngủ của bạn đã vững: "&TEXT(E6,"0")&" điểm, "&G6&" đêm đạt ngưỡng tuần này. Cơ thể bạn đã yên. 30 ngày tới mình chỉ chấm điểm sáng, không giao việc nữa.",IF(LEFT(T6,3)="Gốc","Giấc ngủ lên "&TEXT(E6,"0")&" điểm. Nhưng "&O6&" đêm bạn ăn tối sau 20 giờ, và phần lớn đêm vỡ rơi vào những đêm đó. Mình ở lại thêm 7 ngày, chỉ dời bữa tối sớm hơn nhé.",IF(LEFT(T6,4)="Chưa","Giấc ngủ của bạn đang lên từ "&TEXT(D6,"0")&" lên "&TEXT(E6,"0")&" điểm, chưa đủ vững. Mình đi thêm 7 đêm nữa, không vội.","")))))) | V6: =IF(B6=0,"",IF(SUMPRODUCT(MAX(('Nhật ký'!$A$2:$A$281=$A6)*('Nhật ký'!$U$2:$U$281)))>=Ngưỡng!$B$21,"Căng mức 5 liên tiếp, hỏi riêng; ","")&IF(COUNTIFS('Nhật ký'!$A$2:$A$281,$A6,'Nhật ký'!$H$2:$H$281,"Lo hồi hộp")>=Ngưỡng!$B$22,"Lo hồi hộp nhiều đêm, gợi ý người thật; ","")&IF(SUMPRODUCT(MAX(('Nhật ký'!$A$2:$A$281=$A6)*('Nhật ký'!$V$2:$V$281)))>=Ngưỡng!$B$23,"Tỉnh đêm kéo dài, gợi ý khám; ","")&IF(SUMPRODUCT(MAX(('Nhật ký'!$A$2:$A$281=$A6)*('Nhật ký'!$W$2:$W$281)))>=Ngưỡng!$B$24,"Thiếu dữ liệu nhiều ngày, hỏi một câu; ","")) | W6: =COUNTIFS('Nhật ký'!$A$2:$A$281,$A6,'Nhật ký'!$J$2:$J$281,"Việc",'Nhật ký'!$Q$2:$Q$281,1) -> 0 | X6: =COUNTIFS('Nhật ký'!$A$2:$A$281,$A6,'Nhật ký'!$J$2:$J$281,"Tiền",'Nhật ký'!$Q$2:$Q$281,1) -> 0 | Y6: =COUNTIFS('Nhật ký'!$A$2:$A$281,$A6,'Nhật ký'!$J$2:$J$281,"Người",'Nhật ký'!$Q$2:$Q$281,1) -> 0 | Z6: =COUNTIFS('Nhật ký'!$A$2:$A$281,$A6,'Nhật ký'!$J$2:$J$281,"Không rõ",'Nhật ký'!$Q$2:$Q$281,1) -> 0 | AA6: =IFERROR(AVERAGEIFS('Nhật ký'!$X$2:$X$281,'Nhật ký'!$A$2:$A$281,$A6,'Nhật ký'!$C$2:$C$281,2),"")
A7: P06 | B7: =COUNTIFS('Nhật ký'!$A$2:$A$281,$A7,'Nhật ký'!$O$2:$O$281,1) -> 0 | C7: =COUNTIFS('Nhật ký'!$A$2:$A$281,$A7,'Nhật ký'!$Q$2:$Q$281,1) -> 0 | D7: =IFERROR(AVERAGEIFS('Nhật ký'!$N$2:$N$281,'Nhật ký'!$A$2:$A$281,$A7,'Nhật ký'!$C$2:$C$281,1),"") | E7: =IFERROR(AVERAGEIFS('Nhật ký'!$N$2:$N$281,'Nhật ký'!$A$2:$A$281,$A7,'Nhật ký'!$C$2:$C$281,2),"") | F7: =IF(OR(D7="",E7=""),"",E7-D7) | G7: =COUNTIFS('Nhật ký'!$A$2:$A$281,$A7,'Nhật ký'!$T$2:$T$281,1,'Nhật ký'!$C$2:$C$281,2) -> 0 | H7: =IF(F7="","",IF(AND(F7>=Ngưỡng!$B$11,G7>=Ngưỡng!$B$12),"Có","Chưa")) | I7: =COUNTIFS('Nhật ký'!$A$2:$A$281,$A7,'Nhật ký'!$P$2:$P$281,1) -> 0 | J7: =COUNTIFS('Nhật ký'!$A$2:$A$281,$A7,'Nhật ký'!$P$2:$P$281,1,'Nhật ký'!$Q$2:$Q$281,1) -> 0 | K7: =IFERROR(J7/C7,0) -> 0 | L7: =IFERROR(COUNTIFS('Nhật ký'!$A$2:$A$281,$A7,'Nhật ký'!$P$2:$P$281,1,'Nhật ký'!$Q$2:$Q$281,0)/COUNTIFS('Nhật ký'!$A$2:$A$281,$A7,'Nhật ký'!$Q$2:$Q$281,0),0) -> 0 | M7: =K7-L7 -> 0 | N7: =IFERROR(COUNTIFS('Nhật ký'!$A$2:$A$281,$A7,'Nhật ký'!$R$2:$R$281,1)/14,0) -> 0 | O7: =COUNTIFS('Nhật ký'!$A$2:$A$281,$A7,'Nhật ký'!$S$2:$S$281,1) -> 0 | P7: =IFERROR(COUNTIFS('Nhật ký'!$A$2:$A$281,$A7,'Nhật ký'!$P$2:$P$281,1,'Nhật ký'!$S$2:$S$281,1)/O7,0) -> 0 | Q7: =IFERROR(AVERAGEIFS('Nhật ký'!$G$2:$G$281,'Nhật ký'!$A$2:$A$281,$A7,'Nhật ký'!$C$2:$C$281,2),"") | R7: =COUNTIFS('Nhật ký'!$A$2:$A$281,$A7,'Nhật ký'!$Q$2:$Q$281,1,'Nhật ký'!$C$2:$C$281,2) -> 0 | S7: =IF(MAX(W7:Z7)=0,"chưa rõ",INDEX(Ngưỡng!$D$3:$G$3,MATCH(MAX(W7:Z7),W7:Z7,0))) -> chưa rõ | T7: =IF(B7=0,"",IF(B7<Ngưỡng!$B$8,"Chưa đủ dữ liệu: tổng kết ngủ, thêm 7 ngày",IF(H7<>"Có",IF(AND(ISNUMBER(AA7),AA7>=Ngưỡng!$B$27,ISNUMBER(Q7),Q7<Ngưỡng!$B$19),"Mời Hồi sinh lực","Chưa bám rễ: gia hạn 7 ngày"),IF(AND(O7>=Ngưỡng!$B$26,P7>K7),"Gốc tiêu hóa: ở lại Ngủ 7 ngày, dời bữa tối",IF(AND(C7>=Ngưỡng!$B$9,M7>=Ngưỡng!$B$14,K7>=Ngưỡng!$B$15,OR(N7>=Ngưỡng!$B$16,R7>=Ngưỡng!$B$17)),"Mời Xả áp lực",IF(AND(ISNUMBER(Q7),Q7<Ngưỡng!$B$19),"Mời Hồi sinh lực","Vào Cổng Khỏe")))))) | U7: =IF(T7="","",IF(T7="Mời Xả áp lực","14 đêm qua, giấc ngủ của bạn lên từ "&TEXT(D7,"0")&" lên "&TEXT(E7,"0")&" điểm. Nhưng "&J7&" trong "&I7&" đêm vỡ rơi đúng vào ngày bạn chấm căng từ 4, và phần lớn là căng vì "&S7&". Gốc rễ giờ nằm ở ban ngày, mình sang Xả áp lực nhé?",IF(T7="Mời Hồi sinh lực","Giấc ngủ của bạn đã lên "&TEXT(E7,"0")&" điểm, nhưng tuần này bạn vẫn chỉ chấm sáng dậy trung bình "&TEXT(Q7,"0.0")&" trên 5. Ngủ đủ mà vẫn mệt là chuyện của khí. Mình sang Hồi sinh lực nhé?",IF(T7="Vào Cổng Khỏe","Giấc ngủ của bạn đã vững: "&TEXT(E7,"0")&" điểm, "&G7&" đêm đạt ngưỡng tuần này. Cơ thể bạn đã yên. 30 ngày tới mình chỉ chấm điểm sáng, không giao việc nữa.",IF(LEFT(T7,3)="Gốc","Giấc ngủ lên "&TEXT(E7,"0")&" điểm. Nhưng "&O7&" đêm bạn ăn tối sau 20 giờ, và phần lớn đêm vỡ rơi vào những đêm đó. Mình ở lại thêm 7 ngày, chỉ dời bữa tối sớm hơn nhé.",IF(LEFT(T7,4)="Chưa","Giấc ngủ của bạn đang lên từ "&TEXT(D7,"0")&" lên "&TEXT(E7,"0")&" điểm, chưa đủ vững. Mình đi thêm 7 đêm nữa, không vội.","")))))) | V7: =IF(B7=0,"",IF(SUMPRODUCT(MAX(('Nhật ký'!$A$2:$A$281=$A7)*('Nhật ký'!$U$2:$U$281)))>=Ngưỡng!$B$21,"Căng mức 5 liên tiếp, hỏi riêng; ","")&IF(COUNTIFS('Nhật ký'!$A$2:$A$281,$A7,'Nhật ký'!$H$2:$H$281,"Lo hồi hộp")>=Ngưỡng!$B$22,"Lo hồi hộp nhiều đêm, gợi ý người thật; ","")&IF(SUMPRODUCT(MAX(('Nhật ký'!$A$2:$A$281=$A7)*('Nhật ký'!$V$2:$V$281)))>=Ngưỡng!$B$23,"Tỉnh đêm kéo dài, gợi ý khám; ","")&IF(SUMPRODUCT(MAX(('Nhật ký'!$A$2:$A$281=$A7)*('Nhật ký'!$W$2:$W$281)))>=Ngưỡng!$B$24,"Thiếu dữ liệu nhiều ngày, hỏi một câu; ","")) | W7: =COUNTIFS('Nhật ký'!$A$2:$A$281,$A7,'Nhật ký'!$J$2:$J$281,"Việc",'Nhật ký'!$Q$2:$Q$281,1) -> 0 | X7: =COUNTIFS('Nhật ký'!$A$2:$A$281,$A7,'Nhật ký'!$J$2:$J$281,"Tiền",'Nhật ký'!$Q$2:$Q$281,1) -> 0 | Y7: =COUNTIFS('Nhật ký'!$A$2:$A$281,$A7,'Nhật ký'!$J$2:$J$281,"Người",'Nhật ký'!$Q$2:$Q$281,1) -> 0 | Z7: =COUNTIFS('Nhật ký'!$A$2:$A$281,$A7,'Nhật ký'!$J$2:$J$281,"Không rõ",'Nhật ký'!$Q$2:$Q$281,1) -> 0 | AA7: =IFERROR(AVERAGEIFS('Nhật ký'!$X$2:$X$281,'Nhật ký'!$A$2:$A$281,$A7,'Nhật ký'!$C$2:$C$281,2),"")
A8: P07 | B8: =COUNTIFS('Nhật ký'!$A$2:$A$281,$A8,'Nhật ký'!$O$2:$O$281,1) -> 0 | C8: =COUNTIFS('Nhật ký'!$A$2:$A$281,$A8,'Nhật ký'!$Q$2:$Q$281,1) -> 0 | D8: =IFERROR(AVERAGEIFS('Nhật ký'!$N$2:$N$281,'Nhật ký'!$A$2:$A$281,$A8,'Nhật ký'!$C$2:$C$281,1),"") | E8: =IFERROR(AVERAGEIFS('Nhật ký'!$N$2:$N$281,'Nhật ký'!$A$2:$A$281,$A8,'Nhật ký'!$C$2:$C$281,2),"") | F8: =IF(OR(D8="",E8=""),"",E8-D8) | G8: =COUNTIFS('Nhật ký'!$A$2:$A$281,$A8,'Nhật ký'!$T$2:$T$281,1,'Nhật ký'!$C$2:$C$281,2) -> 0 | H8: =IF(F8="","",IF(AND(F8>=Ngưỡng!$B$11,G8>=Ngưỡng!$B$12),"Có","Chưa")) | I8: =COUNTIFS('Nhật ký'!$A$2:$A$281,$A8,'Nhật ký'!$P$2:$P$281,1) -> 0 | J8: =COUNTIFS('Nhật ký'!$A$2:$A$281,$A8,'Nhật ký'!$P$2:$P$281,1,'Nhật ký'!$Q$2:$Q$281,1) -> 0 | K8: =IFERROR(J8/C8,0) -> 0 | L8: =IFERROR(COUNTIFS('Nhật ký'!$A$2:$A$281,$A8,'Nhật ký'!$P$2:$P$281,1,'Nhật ký'!$Q$2:$Q$281,0)/COUNTIFS('Nhật ký'!$A$2:$A$281,$A8,'Nhật ký'!$Q$2:$Q$281,0),0) -> 0 | M8: =K8-L8 -> 0 | N8: =IFERROR(COUNTIFS('Nhật ký'!$A$2:$A$281,$A8,'Nhật ký'!$R$2:$R$281,1)/14,0) -> 0 | O8: =COUNTIFS('Nhật ký'!$A$2:$A$281,$A8,'Nhật ký'!$S$2:$S$281,1) -> 0 | P8: =IFERROR(COUNTIFS('Nhật ký'!$A$2:$A$281,$A8,'Nhật ký'!$P$2:$P$281,1,'Nhật ký'!$S$2:$S$281,1)/O8,0) -> 0 | Q8: =IFERROR(AVERAGEIFS('Nhật ký'!$G$2:$G$281,'Nhật ký'!$A$2:$A$281,$A8,'Nhật ký'!$C$2:$C$281,2),"") | R8: =COUNTIFS('Nhật ký'!$A$2:$A$281,$A8,'Nhật ký'!$Q$2:$Q$281,1,'Nhật ký'!$C$2:$C$281,2) -> 0 | S8: =IF(MAX(W8:Z8)=0,"chưa rõ",INDEX(Ngưỡng!$D$3:$G$3,MATCH(MAX(W8:Z8),W8:Z8,0))) -> chưa rõ | T8: =IF(B8=0,"",IF(B8<Ngưỡng!$B$8,"Chưa đủ dữ liệu: tổng kết ngủ, thêm 7 ngày",IF(H8<>"Có",IF(AND(ISNUMBER(AA8),AA8>=Ngưỡng!$B$27,ISNUMBER(Q8),Q8<Ngưỡng!$B$19),"Mời Hồi sinh lực","Chưa bám rễ: gia hạn 7 ngày"),IF(AND(O8>=Ngưỡng!$B$26,P8>K8),"Gốc tiêu hóa: ở lại Ngủ 7 ngày, dời bữa tối",IF(AND(C8>=Ngưỡng!$B$9,M8>=Ngưỡng!$B$14,K8>=Ngưỡng!$B$15,OR(N8>=Ngưỡng!$B$16,R8>=Ngưỡng!$B$17)),"Mời Xả áp lực",IF(AND(ISNUMBER(Q8),Q8<Ngưỡng!$B$19),"Mời Hồi sinh lực","Vào Cổng Khỏe")))))) | U8: =IF(T8="","",IF(T8="Mời Xả áp lực","14 đêm qua, giấc ngủ của bạn lên từ "&TEXT(D8,"0")&" lên "&TEXT(E8,"0")&" điểm. Nhưng "&J8&" trong "&I8&" đêm vỡ rơi đúng vào ngày bạn chấm căng từ 4, và phần lớn là căng vì "&S8&". Gốc rễ giờ nằm ở ban ngày, mình sang Xả áp lực nhé?",IF(T8="Mời Hồi sinh lực","Giấc ngủ của bạn đã lên "&TEXT(E8,"0")&" điểm, nhưng tuần này bạn vẫn chỉ chấm sáng dậy trung bình "&TEXT(Q8,"0.0")&" trên 5. Ngủ đủ mà vẫn mệt là chuyện của khí. Mình sang Hồi sinh lực nhé?",IF(T8="Vào Cổng Khỏe","Giấc ngủ của bạn đã vững: "&TEXT(E8,"0")&" điểm, "&G8&" đêm đạt ngưỡng tuần này. Cơ thể bạn đã yên. 30 ngày tới mình chỉ chấm điểm sáng, không giao việc nữa.",IF(LEFT(T8,3)="Gốc","Giấc ngủ lên "&TEXT(E8,"0")&" điểm. Nhưng "&O8&" đêm bạn ăn tối sau 20 giờ, và phần lớn đêm vỡ rơi vào những đêm đó. Mình ở lại thêm 7 ngày, chỉ dời bữa tối sớm hơn nhé.",IF(LEFT(T8,4)="Chưa","Giấc ngủ của bạn đang lên từ "&TEXT(D8,"0")&" lên "&TEXT(E8,"0")&" điểm, chưa đủ vững. Mình đi thêm 7 đêm nữa, không vội.","")))))) | V8: =IF(B8=0,"",IF(SUMPRODUCT(MAX(('Nhật ký'!$A$2:$A$281=$A8)*('Nhật ký'!$U$2:$U$281)))>=Ngưỡng!$B$21,"Căng mức 5 liên tiếp, hỏi riêng; ","")&IF(COUNTIFS('Nhật ký'!$A$2:$A$281,$A8,'Nhật ký'!$H$2:$H$281,"Lo hồi hộp")>=Ngưỡng!$B$22,"Lo hồi hộp nhiều đêm, gợi ý người thật; ","")&IF(SUMPRODUCT(MAX(('Nhật ký'!$A$2:$A$281=$A8)*('Nhật ký'!$V$2:$V$281)))>=Ngưỡng!$B$23,"Tỉnh đêm kéo dài, gợi ý khám; ","")&IF(SUMPRODUCT(MAX(('Nhật ký'!$A$2:$A$281=$A8)*('Nhật ký'!$W$2:$W$281)))>=Ngưỡng!$B$24,"Thiếu dữ liệu nhiều ngày, hỏi một câu; ","")) | W8: =COUNTIFS('Nhật ký'!$A$2:$A$281,$A8,'Nhật ký'!$J$2:$J$281,"Việc",'Nhật ký'!$Q$2:$Q$281,1) -> 0 | X8: =COUNTIFS('Nhật ký'!$A$2:$A$281,$A8,'Nhật ký'!$J$2:$J$281,"Tiền",'Nhật ký'!$Q$2:$Q$281,1) -> 0 | Y8: =COUNTIFS('Nhật ký'!$A$2:$A$281,$A8,'Nhật ký'!$J$2:$J$281,"Người",'Nhật ký'!$Q$2:$Q$281,1) -> 0 | Z8: =COUNTIFS('Nhật ký'!$A$2:$A$281,$A8,'Nhật ký'!$J$2:$J$281,"Không rõ",'Nhật ký'!$Q$2:$Q$281,1) -> 0 | AA8: =IFERROR(AVERAGEIFS('Nhật ký'!$X$2:$X$281,'Nhật ký'!$A$2:$A$281,$A8,'Nhật ký'!$C$2:$C$281,2),"")
